Workbook
Name pToday: SETTINGS!$C$5
Name pCurMonth: SETTINGS!$C$6
Name pUtil1: SETTINGS!$C$7
Name pUtil2: SETTINGS!$C$8
Name pUtil3: SETTINGS!$C$9
Name pWarnDays: SETTINGS!$C$10
Name pCapWarn: SETTINGS!$C$11
Name lstMonths: OFFSET(SETTINGS!$B$15,0,0,MAX(1,COUNTA(SETTINGS!$B$15:$B$114)),1)
Name lstBanks: OFFSET(SETTINGS!$C$15,0,0,MAX(1,COUNTA(SETTINGS!$C$15:$C$114)),1)
Name lstCardTypes: OFFSET(SETTINGS!$D$15,0,0,MAX(1,COUNTA(SETTINGS!$D$15:$D$114)),1)
Name lstNetworks: OFFSET(SETTINGS!$E$15,0,0,MAX(1,COUNTA(SETTINGS!$E$15:$E$114)),1)
Name lstCardStatus: OFFSET(SETTINGS!$F$15,0,0,MAX(1,COUNTA(SETTINGS!$F$15:$F$114)),1)
Name lstTxStatus: OFFSET(SETTINGS!$G$15,0,0,MAX(1,COUNTA(SETTINGS!$G$15:$G$114)),1)
Name lstPayStatus: OFFSET(SETTINGS!$H$15,0,0,MAX(1,COUNTA(SETTINGS!$H$15:$H$114)),1)
Name lstCategories: OFFSET(SETTINGS!$I$15,0,0,MAX(1,COUNTA(SETTINGS!$I$15:$I$114)),1)
Name lstCards: OFFSET(CARDS!$A$5,0,0,MAX(1,COUNTA(CARDS!$A$5:$A$34)),1)
Name lstMCC: OFFSET(MCC_MASTER!$A$5,0,0,MAX(1,COUNTA(MCC_MASTER!$A$5:$A$504)),1)
Name lstRuleIDs: OFFSET(CASHBACK_RULES!$A$5,0,0,MAX(1,SUMPRODUCT(--(CASHBACK_RULES!$A$5:$A$304<>""))),1)

Sheet Dashboard
B2: 💳 CREDIT CARD MANAGER
B3: Quản lý nhiều thẻ · hạn mức · sao kê · cashback theo MCC
B4: Tháng đang xem ▸ | D4: =pCurMonth -> 202610 | E4: ← chọn tháng (dropdown). Muốn quay về tự động: nhập =pCurMonth
B5: ĐIỀU HƯỚNG
B6: =HYPERLINK("#CARDS!A1","CARDS") -> CARDS | D6: =HYPERLINK("#CASHBACK_RULES!A1","CASHBACK_RULES") -> CASHBACK_RULES | F6: =HYPERLINK("#MCC_MASTER!A1","MCC_MASTER") -> MCC_MASTER | H6: =HYPERLINK("#TRANSACTIONS_MASTER!A1","TRANSACTIONS") -> TRANSACTIONS | J6: =HYPERLINK("#CARD_TRACKER!A1","CARD_TRACKER") -> CARD_TRACKER | L6: =HYPERLINK("#CAP_TRACKER!A1","CAP_TRACKER") -> CAP_TRACKER | N6: =HYPERLINK("#SETTINGS!A1","SETTINGS") -> SETTINGS
B7: =HYPERLINK("#'2026-01'!A1","2026-01") -> 2026-01 | C7: =HYPERLINK("#'2026-02'!A1","2026-02") -> 2026-02 | D7: =HYPERLINK("#'2026-03'!A1","2026-03") -> 2026-03 | E7: =HYPERLINK("#'2026-04'!A1","2026-04") -> 2026-04 | F7: =HYPERLINK("#'2026-05'!A1","2026-05") -> 2026-05 | G7: =HYPERLINK("#'2026-06'!A1","2026-06") -> 2026-06 | H7: =HYPERLINK("#'2026-07'!A1","2026-07") -> 2026-07 | I7: =HYPERLINK("#'2026-08'!A1","2026-08") -> 2026-08 | J7: =HYPERLINK("#'2026-09'!A1","2026-09") -> 2026-09 | K7: =HYPERLINK("#'2026-10'!A1","2026-10") -> 2026-10 | L7: =HYPERLINK("#'2026-11'!A1","2026-11") -> 2026-11 | M7: =HYPERLINK("#'2026-12'!A1","2026-12") -> 2026-12
B9: TỔNG SỐ THẺ | D9: TỔNG HẠN MỨC TÍN DỤNG | F9: TỔNG DƯ NỢ HIỆN TẠI | H9: HẠN MỨC CÒN LẠI | J9: TỶ LỆ SỬ DỤNG HẠN MỨC | L9: CHI TIÊU TRONG THÁNG | N9: THẺ CHI TIÊU CAO NHẤT
B10: =COUNTIF(CARD_TRACKER!$D$5:$D$34,"Active") -> 6 | D10: =CARD_TRACKER!E36 -> 185000000 | F10: =CARD_TRACKER!F36 -> 54950000 | H10: =CARD_TRACKER!G36 -> 130050000 | J10: =CARD_TRACKER!H36 -> 0.29702703 | L10: =SUMIFS(TRANSACTIONS_MASTER!$L$5:$L$1204,TRANSACTIONS_MASTER!$C$5:$C$1204,$D$4,TRANSACTIONS_MASTER!$U$5:$U$1204,"<>Cancelled") -> 54150000 | N10: =IF(MAX($D$84:$D$113)>0,INDEX($B$84:$B$113,MATCH(MAX($D$84:$D$113),$D$84:$D$113,0)),"—") -> VPBank JCB Z Card
B11: ="Active / tổng "&COUNTA(CARDS!$A$5:$A$34)&" thẻ" -> Active / tổng 6 thẻ | D11: thẻ Active | F11: chưa thanh toán | H11: khả dụng | J11: =CARD_TRACKER!I36 -> ● Bình thường | L11: ="Tháng "&INT($D$4/100)&"-"&TEXT(MOD($D$4,100),"00") -> Tháng 2026-10 | N11: =IF(MAX($D$84:$D$113)>0,TEXT(MAX($D$84:$D$113),"#,##0")&" ₫","") -> 16,800,000 ₫
B13: CASHBACK DỰ KIẾN | D13: CASHBACK THỰC TẾ | F13: CASHBACK CÒN CÓ THỂ NHẬN | H13: THẺ CASHBACK CAO NHẤT | J13: THẺ GẦN ĐẠT HẠN MỨC | L13: THẺ GẦN ĐẠT CASHBACK CAP | N13: THẺ CẦN CHÚ Ý THANH TOÁN
B14: =SUMIFS(TRANSACTIONS_MASTER!$O$5:$O$1204,TRANSACTIONS_MASTER!$C$5:$C$1204,$D$4) -> 5325000 | D14: =SUMIFS(TRANSACTIONS_MASTER!$Q$5:$Q$1204,TRANSACTIONS_MASTER!$C$5:$C$1204,$D$4) -> 3880000 | F14: =SUM(CAP_TRACKER!$H$60:$H$89) -> 620000 | H14: =IF(MAX($E$84:$E$113)>0,INDEX($B$84:$B$113,MATCH(MAX($E$84:$E$113),$E$84:$E$113,0)),"—") -> VPBank JCB Z Card | J14: =IF(MAX(CARD_TRACKER!$H$5:$H$34)>0,INDEX(CARD_TRACKER!$C$5:$C$34,MATCH(MAX(CARD_TRACKER!$H$5:$H$34),CARD_TRACKER!$H$5:$H$34,0))&" ("&TEXT(MAX(CARD_TRACKER!$H$5:$H$34),"0%")&")","—") -> Cashback Demo D (52%) | L14: =IF(MAX($H$84:$H$113)>0,INDEX($B$84:$B$113,MATCH(MAX($H$84:$H$113),$H$84:$H$113,0))&" ("&TEXT(MAX($H$84:$H$113),"0%")&")","—") -> VPBank JCB Z Card (100%) | N14: =COUNTIF(CARD_TRACKER!$O$5:$O$34,"Quá hạn")+COUNTIF(CARD_TRACKER!$O$5:$O$34,"Đến hạn")+COUNTIF(CARD_TRACKER!$O$5:$O$34,"Sắp đến hạn") -> 1
B15: trước khi áp cap | D15: =IF(B14=0,"đã áp cap",TEXT(D14/B14,"0%")&" so với dự kiến · đã áp cap") -> 73% so với dự kiến · đã áp cap | F15: tối đa còn lại (cap hữu hạn) | H15: =IF(MAX($E$84:$E$113)>0,TEXT(MAX($E$84:$E$113),"#,##0")&" ₫","") -> 1,000,000 ₫ | J15: =COUNTIF(CARD_TRACKER!$H$5:$H$34,">="&pUtil2)&" thẻ ≥ "&TEXT(pUtil2,"0%") -> 0 thẻ ≥ 70% | L15: =COUNTIF($H$84:$H$113,">="&pCapWarn)&" thẻ ≥ "&TEXT(pCapWarn,"0%")&" cap" -> 4 thẻ ≥ 80% cap | N15: =COUNTIF(CARD_TRACKER!$O$5:$O$34,"Quá hạn")&" quá hạn · "&COUNTIF(CARD_TRACKER!$O$5:$O$34,"Đến hạn")&" đến hạn · "&COUNTIF(CARD_TRACKER!$O$5:$O$34,"Sắp đến hạn")&" sắp đến" -> 0 quá hạn · 0 đến hạn · 1 sắp đến
B17: BIỂU ĐỒ
B82: TÌNH TRẠNG TỪNG THẺ — tháng đang xem (dữ liệu cho biểu đồ)
B83: Thẻ | D83: Chi tiêu tháng | E83: Cashback tháng | F83: Cap thẻ / tháng | G83: Cap còn lại | H83: % cap | I83: Hạn mức | J83: Dư nợ | K83: Khả dụng | L83: Utilization | M83: Mức | N83: Thanh toán
B84: =IF(CAP_TRACKER!$C60="","",CAP_TRACKER!D60) -> VPBank JCB Z Card | D84: =IF(CAP_TRACKER!$C60="","",CAP_TRACKER!E60) -> 16800000 | E84: =IF(CAP_TRACKER!$C60="","",CAP_TRACKER!F60) -> 1000000 | F84: =IF(CAP_TRACKER!$C60="","",CAP_TRACKER!G60) -> 1000000 | G84: =IF(CAP_TRACKER!$C60="","",CAP_TRACKER!H60) -> 0 | H84: =IF(CAP_TRACKER!$C60="","",CAP_TRACKER!I60) -> 1 | I84: =IF(CAP_TRACKER!$C60="","",CARD_TRACKER!E5) -> 50000000 | J84: =IF(CAP_TRACKER!$C60="","",CARD_TRACKER!F5) -> 16800000 | K84: =IF(CAP_TRACKER!$C60="","",CARD_TRACKER!G5) -> 33200000 | L84: =IF(CAP_TRACKER!$C60="","",CARD_TRACKER!H5) -> 0.336 | M84: =IF(CAP_TRACKER!$C60="","",CARD_TRACKER!I5) -> ● Bình thường | N84: =IF(CAP_TRACKER!$C60="","",CARD_TRACKER!O5) -> Đã thanh toán
B85: =IF(CAP_TRACKER!$C61="","",CAP_TRACKER!D61) -> VIB Cashback Demo A | D85: =IF(CAP_TRACKER!$C61="","",CAP_TRACKER!E61) -> 11500000 | E85: =IF(CAP_TRACKER!$C61="","",CAP_TRACKER!F61) -> 1000000 | F85: =IF(CAP_TRACKER!$C61="","",CAP_TRACKER!G61) -> 1000000 | G85: =IF(CAP_TRACKER!$C61="","",CAP_TRACKER!H61) -> 0 | H85: =IF(CAP_TRACKER!$C61="","",CAP_TRACKER!I61) -> 1 | I85: =IF(CAP_TRACKER!$C61="","",CARD_TRACKER!E6) -> 30000000 | J85: =IF(CAP_TRACKER!$C61="","",CARD_TRACKER!F6) -> 11500000 | K85: =IF(CAP_TRACKER!$C61="","",CARD_TRACKER!G6) -> 18500000 | L85: =IF(CAP_TRACKER!$C61="","",CARD_TRACKER!H6) -> 0.38333333 | M85: =IF(CAP_TRACKER!$C61="","",CARD_TRACKER!I6) -> ● Bình thường | N85: =IF(CAP_TRACKER!$C61="","",CARD_TRACKER!O6) -> Chưa đến hạn
B86: =IF(CAP_TRACKER!$C62="","",CAP_TRACKER!D62) -> Techcombank Cashback Demo B | D86: =IF(CAP_TRACKER!$C62="","",CAP_TRACKER!E62) -> 8300000 | E86: =IF(CAP_TRACKER!$C62="","",CAP_TRACKER!F62) -> 390000 | F86: =IF(CAP_TRACKER!$C62="","",CAP_TRACKER!G62) -> 2000000 | G86: =IF(CAP_TRACKER!$C62="","",CAP_TRACKER!H62) -> 510000 | H86: =IF(CAP_TRACKER!$C62="","",CAP_TRACKER!I62) -> 0.195 | I86: =IF(CAP_TRACKER!$C62="","",CARD_TRACKER!E7) -> 40000000 | J86: =IF(CAP_TRACKER!$C62="","",CARD_TRACKER!F7) -> 8300000 | K86: =IF(CAP_TRACKER!$C62="","",CARD_TRACKER!G7) -> 31700000 | L86: =IF(CAP_TRACKER!$C62="","",CARD_TRACKER!H7) -> 0.2075 | M86: =IF(CAP_TRACKER!$C62="","",CARD_TRACKER!I7) -> ● Bình thường | N86: =IF(CAP_TRACKER!$C62="","",CARD_TRACKER!O7) -> Đã thanh toán
B87: =IF(CAP_TRACKER!$C63="","",CAP_TRACKER!D63) -> UOB Cashback Demo C | D87: =IF(CAP_TRACKER!$C63="","",CAP_TRACKER!E63) -> 7000000 | E87: =IF(CAP_TRACKER!$C63="","",CAP_TRACKER!F63) -> 1000000 | F87: =IF(CAP_TRACKER!$C63="","",CAP_TRACKER!G63) -> ∞ | G87: =IF(CAP_TRACKER!$C63="","",CAP_TRACKER!H63) -> 0 | H87: =IF(CAP_TRACKER!$C63="","",CAP_TRACKER!I63) -> 1 | I87: =IF(CAP_TRACKER!$C63="","",CARD_TRACKER!E8) -> 25000000 | J87: =IF(CAP_TRACKER!$C63="","",CARD_TRACKER!F8) -> 7000000 | K87: =IF(CAP_TRACKER!$C63="","",CARD_TRACKER!G8) -> 18000000 | L87: =IF(CAP_TRACKER!$C63="","",CARD_TRACKER!H8) -> 0.28 | M87: =IF(CAP_TRACKER!$C63="","",CARD_TRACKER!I8) -> ● Bình thường | N87: =IF(CAP_TRACKER!$C63="","",CARD_TRACKER!O8) -> Đã thanh toán
B88: =IF(CAP_TRACKER!$C64="","",CAP_TRACKER!D64) -> MB Cashback Demo D | D88: =IF(CAP_TRACKER!$C64="","",CAP_TRACKER!E64) -> 9550000 | E88: =IF(CAP_TRACKER!$C64="","",CAP_TRACKER!F64) -> 490000 | F88: =IF(CAP_TRACKER!$C64="","",CAP_TRACKER!G64) -> 600000 | G88: =IF(CAP_TRACKER!$C64="","",CAP_TRACKER!H64) -> 110000 | H88: =IF(CAP_TRACKER!$C64="","",CAP_TRACKER!I64) -> 0.81666667 | I88: =IF(CAP_TRACKER!$C64="","",CARD_TRACKER!E9) -> 20000000 | J88: =IF(CAP_TRACKER!$C64="","",CARD_TRACKER!F9) -> 10350000 | K88: =IF(CAP_TRACKER!$C64="","",CARD_TRACKER!G9) -> 9650000 | L88: =IF(CAP_TRACKER!$C64="","",CARD_TRACKER!H9) -> 0.5175 | M88: =IF(CAP_TRACKER!$C64="","",CARD_TRACKER!I9) -> ● Cảnh báo nhẹ | N88: =IF(CAP_TRACKER!$C64="","",CARD_TRACKER!O9) -> Sắp đến hạn
B89: =IF(CAP_TRACKER!$C65="","",CAP_TRACKER!D65) -> ACB Demo E (không cashback) | D89: =IF(CAP_TRACKER!$C65="","",CAP_TRACKER!E65) -> 1000000 | E89: =IF(CAP_TRACKER!$C65="","",CAP_TRACKER!F65) -> 0 | F89: =IF(CAP_TRACKER!$C65="","",CAP_TRACKER!G65) -> ∞ | G89: =IF(CAP_TRACKER!$C65="","",CAP_TRACKER!H65) -> 0 | H89: =IF(CAP_TRACKER!$C65="","",CAP_TRACKER!I65) -> 0 | I89: =IF(CAP_TRACKER!$C65="","",CARD_TRACKER!E10) -> 20000000 | J89: =IF(CAP_TRACKER!$C65="","",CARD_TRACKER!F10) -> 1000000 | K89: =IF(CAP_TRACKER!$C65="","",CARD_TRACKER!G10) -> 19000000 | L89: =IF(CAP_TRACKER!$C65="","",CARD_TRACKER!H10) -> 0.05 | M89: =IF(CAP_TRACKER!$C65="","",CARD_TRACKER!I10) -> ● Bình thường | N89: =IF(CAP_TRACKER!$C65="","",CARD_TRACKER!O10) -> Đã thanh toán
B90: =IF(CAP_TRACKER!$C66="","",CAP_TRACKER!D66) | D90: =IF(CAP_TRACKER!$C66="","",CAP_TRACKER!E66) | E90: =IF(CAP_TRACKER!$C66="","",CAP_TRACKER!F66) | F90: =IF(CAP_TRACKER!$C66="","",CAP_TRACKER!G66) | G90: =IF(CAP_TRACKER!$C66="","",CAP_TRACKER!H66) | H90: =IF(CAP_TRACKER!$C66="","",CAP_TRACKER!I66) | I90: =IF(CAP_TRACKER!$C66="","",CARD_TRACKER!E11) | J90: =IF(CAP_TRACKER!$C66="","",CARD_TRACKER!F11) | K90: =IF(CAP_TRACKER!$C66="","",CARD_TRACKER!G11) | L90: =IF(CAP_TRACKER!$C66="","",CARD_TRACKER!H11) | M90: =IF(CAP_TRACKER!$C66="","",CARD_TRACKER!I11) | N90: =IF(CAP_TRACKER!$C66="","",CARD_TRACKER!O11)
B91: =IF(CAP_TRACKER!$C67="","",CAP_TRACKER!D67) | D91: =IF(CAP_TRACKER!$C67="","",CAP_TRACKER!E67) | E91: =IF(CAP_TRACKER!$C67="","",CAP_TRACKER!F67) | F91: =IF(CAP_TRACKER!$C67="","",CAP_TRACKER!G67) | G91: =IF(CAP_TRACKER!$C67="","",CAP_TRACKER!H67) | H91: =IF(CAP_TRACKER!$C67="","",CAP_TRACKER!I67) | I91: =IF(CAP_TRACKER!$C67="","",CARD_TRACKER!E12) | J91: =IF(CAP_TRACKER!$C67="","",CARD_TRACKER!F12) | K91: =IF(CAP_TRACKER!$C67="","",CARD_TRACKER!G12) | L91: =IF(CAP_TRACKER!$C67="","",CARD_TRACKER!H12) | M91: =IF(CAP_TRACKER!$C67="","",CARD_TRACKER!I12) | N91: =IF(CAP_TRACKER!$C67="","",CARD_TRACKER!O12)
B92: =IF(CAP_TRACKER!$C68="","",CAP_TRACKER!D68) | D92: =IF(CAP_TRACKER!$C68="","",CAP_TRACKER!E68) | E92: =IF(CAP_TRACKER!$C68="","",CAP_TRACKER!F68) | F92: =IF(CAP_TRACKER!$C68="","",CAP_TRACKER!G68) | G92: =IF(CAP_TRACKER!$C68="","",CAP_TRACKER!H68) | H92: =IF(CAP_TRACKER!$C68="","",CAP_TRACKER!I68) | I92: =IF(CAP_TRACKER!$C68="","",CARD_TRACKER!E13) | J92: =IF(CAP_TRACKER!$C68="","",CARD_TRACKER!F13) | K92: =IF(CAP_TRACKER!$C68="","",CARD_TRACKER!G13) | L92: =IF(CAP_TRACKER!$C68="","",CARD_TRACKER!H13) | M92: =IF(CAP_TRACKER!$C68="","",CARD_TRACKER!I13) | N92: =IF(CAP_TRACKER!$C68="","",CARD_TRACKER!O13)
B93: =IF(CAP_TRACKER!$C69="","",CAP_TRACKER!D69) | D93: =IF(CAP_TRACKER!$C69="","",CAP_TRACKER!E69) | E93: =IF(CAP_TRACKER!$C69="","",CAP_TRACKER!F69) | F93: =IF(CAP_TRACKER!$C69="","",CAP_TRACKER!G69) | G93: =IF(CAP_TRACKER!$C69="","",CAP_TRACKER!H69) | H93: =IF(CAP_TRACKER!$C69="","",CAP_TRACKER!I69) | I93: =IF(CAP_TRACKER!$C69="","",CARD_TRACKER!E14) | J93: =IF(CAP_TRACKER!$C69="","",CARD_TRACKER!F14) | K93: =IF(CAP_TRACKER!$C69="","",CARD_TRACKER!G14) | L93: =IF(CAP_TRACKER!$C69="","",CARD_TRACKER!H14) | M93: =IF(CAP_TRACKER!$C69="","",CARD_TRACKER!I14) | N93: =IF(CAP_TRACKER!$C69="","",CARD_TRACKER!O14)
B94: =IF(CAP_TRACKER!$C70="","",CAP_TRACKER!D70) | D94: =IF(CAP_TRACKER!$C70="","",CAP_TRACKER!E70) | E94: =IF(CAP_TRACKER!$C70="","",CAP_TRACKER!F70) | F94: =IF(CAP_TRACKER!$C70="","",CAP_TRACKER!G70) | G94: =IF(CAP_TRACKER!$C70="","",CAP_TRACKER!H70) | H94: =IF(CAP_TRACKER!$C70="","",CAP_TRACKER!I70) | I94: =IF(CAP_TRACKER!$C70="","",CARD_TRACKER!E15) | J94: =IF(CAP_TRACKER!$C70="","",CARD_TRACKER!F15) | K94: =IF(CAP_TRACKER!$C70="","",CARD_TRACKER!G15) | L94: =IF(CAP_TRACKER!$C70="","",CARD_TRACKER!H15) | M94: =IF(CAP_TRACKER!$C70="","",CARD_TRACKER!I15) | N94: =IF(CAP_TRACKER!$C70="","",CARD_TRACKER!O15)
B95: =IF(CAP_TRACKER!$C71="","",CAP_TRACKER!D71) | D95: =IF(CAP_TRACKER!$C71="","",CAP_TRACKER!E71) | E95: =IF(CAP_TRACKER!$C71="","",CAP_TRACKER!F71) | F95: =IF(CAP_TRACKER!$C71="","",CAP_TRACKER!G71) | G95: =IF(CAP_TRACKER!$C71="","",CAP_TRACKER!H71) | H95: =IF(CAP_TRACKER!$C71="","",CAP_TRACKER!I71) | I95: =IF(CAP_TRACKER!$C71="","",CARD_TRACKER!E16) | J95: =IF(CAP_TRACKER!$C71="","",CARD_TRACKER!F16) | K95: =IF(CAP_TRACKER!$C71="","",CARD_TRACKER!G16) | L95: =IF(CAP_TRACKER!$C71="","",CARD_TRACKER!H16) | M95: =IF(CAP_TRACKER!$C71="","",CARD_TRACKER!I16) | N95: =IF(CAP_TRACKER!$C71="","",CARD_TRACKER!O16)
... B113: =IF(CAP_TRACKER!$C89="","",CAP_TRACKER!D89) | D113: =IF(CAP_TRACKER!$C89="","",CAP_TRACKER!E89) | E113: =IF(CAP_TRACKER!$C89="","",CAP_TRACKER!F89) | F113: =IF(CAP_TRACKER!$C89="","",CAP_TRACKER!G89) | G113: =IF(CAP_TRACKER!$C89="","",CAP_TRACKER!H89) | H113: =IF(CAP_TRACKER!$C89="","",CAP_TRACKER!I89) | I113: =IF(CAP_TRACKER!$C89="","",CARD_TRACKER!E34) | J113: =IF(CAP_TRACKER!$C89="","",CARD_TRACKER!F34) | K113: =IF(CAP_TRACKER!$C89="","",CARD_TRACKER!G34) | L113: =IF(CAP_TRACKER!$C89="","",CARD_TRACKER!H34) | M113: =IF(CAP_TRACKER!$C89="","",CARD_TRACKER!I34) | N113: =IF(CAP_TRACKER!$C89="","",CARD_TRACKER!O34)
B116: CHI TIÊU THEO DANH MỤC — tháng đang xem | H116: CHI TIÊU & CASHBACK THEO THÁNG — cả năm
B117: Danh mục | D117: Chi tiêu | E117: Cashback | H117: Tháng | J117: Chi tiêu | K117: Cashback dự kiến | L117: Cashback thực tế | M117: Số GD
B118: =IFERROR(INDEX(TRANSACTIONS_MASTER!$K$5:$K$1204,IFERROR(MATCH(1,INDEX((TRANSACTIONS_MASTER!$C$5:$C$1204=$D$4)*(TRANSACTIONS_MASTER!$AL$5:$AL$1204=1),0),0),"")),"") -> Fitness & Wellness | D118: =IF($B118="","",SUMIFS(TRANSACTIONS_MASTER!$L$5:$L$1204,TRANSACTIONS_MASTER!$K$5:$K$1204,$B118,TRANSACTIONS_MASTER!$C$5:$C$1204,$D$4,TRANSACTIONS_MASTER!$U$5:$U$1204,"<>Cancelled")) -> 10000000 | E118: =IF($B118="","",SUMIFS(TRANSACTIONS_MASTER!$Q$5:$Q$1204,TRANSACTIONS_MASTER!$K$5:$K$1204,$B118,TRANSACTIONS_MASTER!$C$5:$C$1204,$D$4)) -> 500000 | H118: =INT($D$4/100)&"-"&TEXT(1,"00") -> 2026-01 | J118: =SUMIFS(TRANSACTIONS_MASTER!$L$5:$L$1204,TRANSACTIONS_MASTER!$C$5:$C$1204,(INT($D$4/100)*100+1),TRANSACTIONS_MASTER!$U$5:$U$1204,"<>Cancelled") -> 0 | K118: =SUMIFS(TRANSACTIONS_MASTER!$O$5:$O$1204,TRANSACTIONS_MASTER!$C$5:$C$1204,(INT($D$4/100)*100+1)) -> 0 | L118: =SUMIFS(TRANSACTIONS_MASTER!$Q$5:$Q$1204,TRANSACTIONS_MASTER!$C$5:$C$1204,(INT($D$4/100)*100+1)) -> 0 | M118: =COUNTIFS(TRANSACTIONS_MASTER!$C$5:$C$1204,(INT($D$4/100)*100+1),TRANSACTIONS_MASTER!$U$5:$U$1204,"<>Cancelled") -> 0
B119: =IFERROR(INDEX(TRANSACTIONS_MASTER!$K$5:$K$1204,IFERROR(MATCH(1,INDEX((TRANSACTIONS_MASTER!$C$5:$C$1204=$D$4)*(TRANSACTIONS_MASTER!$AL$5:$AL$1204=2),0),0),"")),"") -> Dining | D119: =IF($B119="","",SUMIFS(TRANSACTIONS_MASTER!$L$5:$L$1204,TRANSACTIONS_MASTER!$K$5:$K$1204,$B119,TRANSACTIONS_MASTER!$C$5:$C$1204,$D$4,TRANSACTIONS_MASTER!$U$5:$U$1204,"<>Cancelled")) -> 16800000 | E119: =IF($B119="","",SUMIFS(TRANSACTIONS_MASTER!$Q$5:$Q$1204,TRANSACTIONS_MASTER!$K$5:$K$1204,$B119,TRANSACTIONS_MASTER!$C$5:$C$1204,$D$4)) -> 1850000 | H119: =INT($D$4/100)&"-"&TEXT(2,"00") -> 2026-02 | J119: =SUMIFS(TRANSACTIONS_MASTER!$L$5:$L$1204,TRANSACTIONS_MASTER!$C$5:$C$1204,(INT($D$4/100)*100+2),TRANSACTIONS_MASTER!$U$5:$U$1204,"<>Cancelled") -> 0 | K119: =SUMIFS(TRANSACTIONS_MASTER!$O$5:$O$1204,TRANSACTIONS_MASTER!$C$5:$C$1204,(INT($D$4/100)*100+2)) -> 0 | L119: =SUMIFS(TRANSACTIONS_MASTER!$Q$5:$Q$1204,TRANSACTIONS_MASTER!$C$5:$C$1204,(INT($D$4/100)*100+2)) -> 0 | M119: =COUNTIFS(TRANSACTIONS_MASTER!$C$5:$C$1204,(INT($D$4/100)*100+2),TRANSACTIONS_MASTER!$U$5:$U$1204,"<>Cancelled") -> 0
B120: =IFERROR(INDEX(TRANSACTIONS_MASTER!$K$5:$K$1204,IFERROR(MATCH(1,INDEX((TRANSACTIONS_MASTER!$C$5:$C$1204=$D$4)*(TRANSACTIONS_MASTER!$AL$5:$AL$1204=3),0),0),"")),"") -> Groceries | D120: =IF($B120="","",SUMIFS(TRANSACTIONS_MASTER!$L$5:$L$1204,TRANSACTIONS_MASTER!$K$5:$K$1204,$B120,TRANSACTIONS_MASTER!$C$5:$C$1204,$D$4,TRANSACTIONS_MASTER!$U$5:$U$1204,"<>Cancelled")) -> 7050000 | E120: =IF($B120="","",SUMIFS(TRANSACTIONS_MASTER!$Q$5:$Q$1204,TRANSACTIONS_MASTER!$K$5:$K$1204,$B120,TRANSACTIONS_MASTER!$C$5:$C$1204,$D$4)) -> 530000 | H120: =INT($D$4/100)&"-"&TEXT(3,"00") -> 2026-03 | J120: =SUMIFS(TRANSACTIONS_MASTER!$L$5:$L$1204,TRANSACTIONS_MASTER!$C$5:$C$1204,(INT($D$4/100)*100+3),TRANSACTIONS_MASTER!$U$5:$U$1204,"<>Cancelled") -> 0 | K120: =SUMIFS(TRANSACTIONS_MASTER!$O$5:$O$1204,TRANSACTIONS_MASTER!$C$5:$C$1204,(INT($D$4/100)*100+3)) -> 0 | L120: =SUMIFS(TRANSACTIONS_MASTER!$Q$5:$Q$1204,TRANSACTIONS_MASTER!$C$5:$C$1204,(INT($D$4/100)*100+3)) -> 0 | M120: =COUNTIFS(TRANSACTIONS_MASTER!$C$5:$C$1204,(INT($D$4/100)*100+3),TRANSACTIONS_MASTER!$U$5:$U$1204,"<>Cancelled") -> 0
B121: =IFERROR(INDEX(TRANSACTIONS_MASTER!$K$5:$K$1204,IFERROR(MATCH(1,INDEX((TRANSACTIONS_MASTER!$C$5:$C$1204=$D$4)*(TRANSACTIONS_MASTER!$AL$5:$AL$1204=4),0),0),"")),"") -> Fuel | D121: =IF($B121="","",SUMIFS(TRANSACTIONS_MASTER!$L$5:$L$1204,TRANSACTIONS_MASTER!$K$5:$K$1204,$B121,TRANSACTIONS_MASTER!$C$5:$C$1204,$D$4,TRANSACTIONS_MASTER!$U$5:$U$1204,"<>Cancelled")) -> 8500000 | E121: =IF($B121="","",SUMIFS(TRANSACTIONS_MASTER!$Q$5:$Q$1204,TRANSACTIONS_MASTER!$K$5:$K$1204,$B121,TRANSACTIONS_MASTER!$C$5:$C$1204,$D$4)) -> 360000 | H121: =INT($D$4/100)&"-"&TEXT(4,"00") -> 2026-04 | J121: =SUMIFS(TRANSACTIONS_MASTER!$L$5:$L$1204,TRANSACTIONS_MASTER!$C$5:$C$1204,(INT($D$4/100)*100+4),TRANSACTIONS_MASTER!$U$5:$U$1204,"<>Cancelled") -> 0 | K121: =SUMIFS(TRANSACTIONS_MASTER!$O$5:$O$1204,TRANSACTIONS_MASTER!$C$5:$C$1204,(INT($D$4/100)*100+4)) -> 0 | L121: =SUMIFS(TRANSACTIONS_MASTER!$Q$5:$Q$1204,TRANSACTIONS_MASTER!$C$5:$C$1204,(INT($D$4/100)*100+4)) -> 0 | M121: =COUNTIFS(TRANSACTIONS_MASTER!$C$5:$C$1204,(INT($D$4/100)*100+4),TRANSACTIONS_MASTER!$U$5:$U$1204,"<>Cancelled") -> 0
B122: =IFERROR(INDEX(TRANSACTIONS_MASTER!$K$5:$K$1204,IFERROR(MATCH(1,INDEX((TRANSACTIONS_MASTER!$C$5:$C$1204=$D$4)*(TRANSACTIONS_MASTER!$AL$5:$AL$1204=5),0),0),"")),"") -> Shopping | D122: =IF($B122="","",SUMIFS(TRANSACTIONS_MASTER!$L$5:$L$1204,TRANSACTIONS_MASTER!$K$5:$K$1204,$B122,TRANSACTIONS_MASTER!$C$5:$C$1204,$D$4,TRANSACTIONS_MASTER!$U$5:$U$1204,"<>Cancelled")) -> 9000000 | E122: =IF($B122="","",SUMIFS(TRANSACTIONS_MASTER!$Q$5:$Q$1204,TRANSACTIONS_MASTER!$K$5:$K$1204,$B122,TRANSACTIONS_MASTER!$C$5:$C$1204,$D$4)) -> 500000 | H122: =INT($D$4/100)&"-"&TEXT(5,"00") -> 2026-05 | J122: =SUMIFS(TRANSACTIONS_MASTER!$L$5:$L$1204,TRANSACTIONS_MASTER!$C$5:$C$1204,(INT($D$4/100)*100+5),TRANSACTIONS_MASTER!$U$5:$U$1204,"<>Cancelled") -> 0 | K122: =SUMIFS(TRANSACTIONS_MASTER!$O$5:$O$1204,TRANSACTIONS_MASTER!$C$5:$C$1204,(INT($D$4/100)*100+5)) -> 0 | L122: =SUMIFS(TRANSACTIONS_MASTER!$Q$5:$Q$1204,TRANSACTIONS_MASTER!$C$5:$C$1204,(INT($D$4/100)*100+5)) -> 0 | M122: =COUNTIFS(TRANSACTIONS_MASTER!$C$5:$C$1204,(INT($D$4/100)*100+5),TRANSACTIONS_MASTER!$U$5:$U$1204,"<>Cancelled") -> 0
B123: =IFERROR(INDEX(TRANSACTIONS_MASTER!$K$5:$K$1204,IFERROR(MATCH(1,INDEX((TRANSACTIONS_MASTER!$C$5:$C$1204=$D$4)*(TRANSACTIONS_MASTER!$AL$5:$AL$1204=6),0),0),"")),"") -> Transport | D123: =IF($B123="","",SUMIFS(TRANSACTIONS_MASTER!$L$5:$L$1204,TRANSACTIONS_MASTER!$K$5:$K$1204,$B123,TRANSACTIONS_MASTER!$C$5:$C$1204,$D$4,TRANSACTIONS_MASTER!$U$5:$U$1204,"<>Cancelled")) -> 1000000 | E123: =IF($B123="","",SUMIFS(TRANSACTIONS_MASTER!$Q$5:$Q$1204,TRANSACTIONS_MASTER!$K$5:$K$1204,$B123,TRANSACTIONS_MASTER!$C$5:$C$1204,$D$4)) -> 50000 | H123: =INT($D$4/100)&"-"&TEXT(6,"00") -> 2026-06 | J123: =SUMIFS(TRANSACTIONS_MASTER!$L$5:$L$1204,TRANSACTIONS_MASTER!$C$5:$C$1204,(INT($D$4/100)*100+6),TRANSACTIONS_MASTER!$U$5:$U$1204,"<>Cancelled") -> 0 | K123: =SUMIFS(TRANSACTIONS_MASTER!$O$5:$O$1204,TRANSACTIONS_MASTER!$C$5:$C$1204,(INT($D$4/100)*100+6)) -> 0 | L123: =SUMIFS(TRANSACTIONS_MASTER!$Q$5:$Q$1204,TRANSACTIONS_MASTER!$C$5:$C$1204,(INT($D$4/100)*100+6)) -> 0 | M123: =COUNTIFS(TRANSACTIONS_MASTER!$C$5:$C$1204,(INT($D$4/100)*100+6),TRANSACTIONS_MASTER!$U$5:$U$1204,"<>Cancelled") -> 0
B124: =IFERROR(INDEX(TRANSACTIONS_MASTER!$K$5:$K$1204,IFERROR(MATCH(1,INDEX((TRANSACTIONS_MASTER!$C$5:$C$1204=$D$4)*(TRANSACTIONS_MASTER!$AL$5:$AL$1204=7),0),0),"")),"") -> Healthcare | D124: =IF($B124="","",SUMIFS(TRANSACTIONS_MASTER!$L$5:$L$1204,TRANSACTIONS_MASTER!$K$5:$K$1204,$B124,TRANSACTIONS_MASTER!$C$5:$C$1204,$D$4,TRANSACTIONS_MASTER!$U$5:$U$1204,"<>Cancelled")) -> 1500000 | E124: =IF($B124="","",SUMIFS(TRANSACTIONS_MASTER!$Q$5:$Q$1204,TRANSACTIONS_MASTER!$K$5:$K$1204,$B124,TRANSACTIONS_MASTER!$C$5:$C$1204,$D$4)) -> 75000 | H124: =INT($D$4/100)&"-"&TEXT(7,"00") -> 2026-07 | J124: =SUMIFS(TRANSACTIONS_MASTER!$L$5:$L$1204,TRANSACTIONS_MASTER!$C$5:$C$1204,(INT($D$4/100)*100+7),TRANSACTIONS_MASTER!$U$5:$U$1204,"<>Cancelled") -> 0 | K124: =SUMIFS(TRANSACTIONS_MASTER!$O$5:$O$1204,TRANSACTIONS_MASTER!$C$5:$C$1204,(INT($D$4/100)*100+7)) -> 0 | L124: =SUMIFS(TRANSACTIONS_MASTER!$Q$5:$Q$1204,TRANSACTIONS_MASTER!$C$5:$C$1204,(INT($D$4/100)*100+7)) -> 0 | M124: =COUNTIFS(TRANSACTIONS_MASTER!$C$5:$C$1204,(INT($D$4/100)*100+7),TRANSACTIONS_MASTER!$U$5:$U$1204,"<>Cancelled") -> 0
B125: =IFERROR(INDEX(TRANSACTIONS_MASTER!$K$5:$K$1204,IFERROR(MATCH(1,INDEX((TRANSACTIONS_MASTER!$C$5:$C$1204=$D$4)*(TRANSACTIONS_MASTER!$AL$5:$AL$1204=8),0),0),"")),"") -> Utilities & Telecom | D125: =IF($B125="","",SUMIFS(TRANSACTIONS_MASTER!$L$5:$L$1204,TRANSACTIONS_MASTER!$K$5:$K$1204,$B125,TRANSACTIONS_MASTER!$C$5:$C$1204,$D$4,TRANSACTIONS_MASTER!$U$5:$U$1204,"<>Cancelled")) -> 300000 | E125: =IF($B125="","",SUMIFS(TRANSACTIONS_MASTER!$Q$5:$Q$1204,TRANSACTIONS_MASTER!$K$5:$K$1204,$B125,TRANSACTIONS_MASTER!$C$5:$C$1204,$D$4)) -> 15000 | H125: =INT($D$4/100)&"-"&TEXT(8,"00") -> 2026-08 | J125: =SUMIFS(TRANSACTIONS_MASTER!$L$5:$L$1204,TRANSACTIONS_MASTER!$C$5:$C$1204,(INT($D$4/100)*100+8),TRANSACTIONS_MASTER!$U$5:$U$1204,"<>Cancelled") -> 0 | K125: =SUMIFS(TRANSACTIONS_MASTER!$O$5:$O$1204,TRANSACTIONS_MASTER!$C$5:$C$1204,(INT($D$4/100)*100+8)) -> 0 | L125: =SUMIFS(TRANSACTIONS_MASTER!$Q$5:$Q$1204,TRANSACTIONS_MASTER!$C$5:$C$1204,(INT($D$4/100)*100+8)) -> 0 | M125: =COUNTIFS(TRANSACTIONS_MASTER!$C$5:$C$1204,(INT($D$4/100)*100+8),TRANSACTIONS_MASTER!$U$5:$U$1204,"<>Cancelled") -> 0
B126: =IFERROR(INDEX(TRANSACTIONS_MASTER!$K$5:$K$1204,IFERROR(MATCH(1,INDEX((TRANSACTIONS_MASTER!$C$5:$C$1204=$D$4)*(TRANSACTIONS_MASTER!$AL$5:$AL$1204=9),0),0),"")),"") | D126: =IF($B126="","",SUMIFS(TRANSACTIONS_MASTER!$L$5:$L$1204,TRANSACTIONS_MASTER!$K$5:$K$1204,$B126,TRANSACTIONS_MASTER!$C$5:$C$1204,$D$4,TRANSACTIONS_MASTER!$U$5:$U$1204,"<>Cancelled")) | E126: =IF($B126="","",SUMIFS(TRANSACTIONS_MASTER!$Q$5:$Q$1204,TRANSACTIONS_MASTER!$K$5:$K$1204,$B126,TRANSACTIONS_MASTER!$C$5:$C$1204,$D$4)) | H126: =INT($D$4/100)&"-"&TEXT(9,"00") -> 2026-09 | J126: =SUMIFS(TRANSACTIONS_MASTER!$L$5:$L$1204,TRANSACTIONS_MASTER!$C$5:$C$1204,(INT($D$4/100)*100+9),TRANSACTIONS_MASTER!$U$5:$U$1204,"<>Cancelled") -> 9650000 | K126: =SUMIFS(TRANSACTIONS_MASTER!$O$5:$O$1204,TRANSACTIONS_MASTER!$C$5:$C$1204,(INT($D$4/100)*100+9)) -> 1098500 | L126: =SUMIFS(TRANSACTIONS_MASTER!$Q$5:$Q$1204,TRANSACTIONS_MASTER!$C$5:$C$1204,(INT($D$4/100)*100+9)) -> 826000 | M126: =COUNTIFS(TRANSACTIONS_MASTER!$C$5:$C$1204,(INT($D$4/100)*100+9),TRANSACTIONS_MASTER!$U$5:$U$1204,"<>Cancelled") -> 6
B127: =IFERROR(INDEX(TRANSACTIONS_MASTER!$K$5:$K$1204,IFERROR(MATCH(1,INDEX((TRANSACTIONS_MASTER!$C$5:$C$1204=$D$4)*(TRANSACTIONS_MASTER!$AL$5:$AL$1204=10),0),0),"")),"") | D127: =IF($B127="","",SUMIFS(TRANSACTIONS_MASTER!$L$5:$L$1204,TRANSACTIONS_MASTER!$K$5:$K$1204,$B127,TRANSACTIONS_MASTER!$C$5:$C$1204,$D$4,TRANSACTIONS_MASTER!$U$5:$U$1204,"<>Cancelled")) | E127: =IF($B127="","",SUMIFS(TRANSACTIONS_MASTER!$Q$5:$Q$1204,TRANSACTIONS_MASTER!$K$5:$K$1204,$B127,TRANSACTIONS_MASTER!$C$5:$C$1204,$D$4)) | H127: =INT($D$4/100)&"-"&TEXT(10,"00") -> 2026-10 | J127: =SUMIFS(TRANSACTIONS_MASTER!$L$5:$L$1204,TRANSACTIONS_MASTER!$C$5:$C$1204,(INT($D$4/100)*100+10),TRANSACTIONS_MASTER!$U$5:$U$1204,"<>Cancelled") -> 54150000 | K127: =SUMIFS(TRANSACTIONS_MASTER!$O$5:$O$1204,TRANSACTIONS_MASTER!$C$5:$C$1204,(INT($D$4/100)*100+10)) -> 5325000 | L127: =SUMIFS(TRANSACTIONS_MASTER!$Q$5:$Q$1204,TRANSACTIONS_MASTER!$C$5:$C$1204,(INT($D$4/100)*100+10)) -> 3880000 | M127: =COUNTIFS(TRANSACTIONS_MASTER!$C$5:$C$1204,(INT($D$4/100)*100+10),TRANSACTIONS_MASTER!$U$5:$U$1204,"<>Cancelled") -> 23
...

Sheet CARDS
A1: 💳 CARDS — danh sách thẻ tín dụng
A2: Không lưu số thẻ đầy đủ / CVV — chỉ 4 số cuối. Ngày sao kê & ngày thanh toán = ngày trong tháng (1–31).
A3: ⚠ SAMPLE DATA — có thể xóa · ✎ ô chữ xanh = nhập liệu · ⚙ ô nền xám = tự động (không sửa)
A4: Card ID | B4: Ngân hàng | C4: Tên thẻ | D4: Loại thẻ | E4: Network | F4: Số cuối thẻ | G4: Hạn mức tín dụng | H4: Ngày sao kê | I4: Ngày thanh toán | J4: Ngày mở thẻ | K4: Phí thường niên | L4: Phí thường niên năm đầu | M4: Trạng thái | N4: Ghi chú | O4: Bank # (helper)
A5: VPB-JCBZ | B5: VPBank | C5: JCB Z Card | D5: Cashback | E5: JCB | F5: 1111 | G5: 50000000 | H5: 25 | I5: 15 | J5: 45361 | K5: 1000000 | L5: 0 | M5: Active | N5: SAMPLE DATA — có thể xóa | O5: =IF(B5="","",IF(COUNTIF($B$5:$B5,B5)=1,MAX($O$4:$O4)+1,"")) -> 1
A6: VIB-A | B6: VIB | C6: Cashback Demo A | D6: Cashback | E6: Mastercard | F6: 2222 | G6: 30000000 | H6: 5 | I6: 25 | J6: 45078 | K6: 600000 | L6: 0 | M6: Active | N6: SAMPLE DATA — có thể xóa (rule minh họa 10% / 500k / 1tr) | O6: =IF(B6="","",IF(COUNTIF($B$5:$B6,B6)=1,MAX($O$4:$O5)+1,"")) -> 2
A7: TCB-B | B7: Techcombank | C7: Cashback Demo B | D7: Platinum | E7: Visa | F7: 3333 | G7: 40000000 | H7: 20 | I7: 10 | J7: 44880 | K7: 800000 | L7: 0 | M7: Active | N7: SAMPLE DATA — có thể xóa (5% / 300k / 2tr) | O7: =IF(B7="","",IF(COUNTIF($B$5:$B7,B7)=1,MAX($O$4:$O6)+1,"")) -> 3
A8: UOB-C | B8: UOB | C8: Cashback Demo C | D8: Cashback | E8: Visa | F8: 4444 | G8: 25000000 | H8: 10 | I8: 28 | J8: 45677 | K8: 0 | L8: 0 | M8: Active | N8: SAMPLE DATA — có thể xóa (15% / 1tr, không cap thẻ) | O8: =IF(B8="","",IF(COUNTIF($B$5:$B8,B8)=1,MAX($O$4:$O7)+1,"")) -> 4
A9: MB-D | B9: MB | C9: Cashback Demo D | D9: Credit | E9: Mastercard | F9: 5555 | G9: 20000000 | H9: 1 | I9: 8 | J9: 45509 | K9: 300000 | L9: 0 | M9: Active | N9: SAMPLE DATA — có thể xóa (rate theo từng MCC) | O9: =IF(B9="","",IF(COUNTIF($B$5:$B9,B9)=1,MAX($O$4:$O8)+1,"")) -> 5
A10: ACB-E | B10: ACB | C10: Demo E (không cashback) | D10: Credit | E10: Visa | F10: 6666 | G10: 20000000 | H10: 15 | I10: 3 | J10: 44288 | K10: 500000 | L10: 0 | M10: Active | N10: SAMPLE DATA — có thể xóa (thẻ không có rule) | O10: =IF(B10="","",IF(COUNTIF($B$5:$B10,B10)=1,MAX($O$4:$O9)+1,"")) -> 6
O11: =IF(B11="","",IF(COUNTIF($B$5:$B11,B11)=1,MAX($O$4:$O10)+1,""))
O12: =IF(B12="","",IF(COUNTIF($B$5:$B12,B12)=1,MAX($O$4:$O11)+1,""))
O13: =IF(B13="","",IF(COUNTIF($B$5:$B13,B13)=1,MAX($O$4:$O12)+1,""))
O14: =IF(B14="","",IF(COUNTIF($B$5:$B14,B14)=1,MAX($O$4:$O13)+1,""))
O15: =IF(B15="","",IF(COUNTIF($B$5:$B15,B15)=1,MAX($O$4:$O14)+1,""))
O16: =IF(B16="","",IF(COUNTIF($B$5:$B16,B16)=1,MAX($O$4:$O15)+1,""))
O17: =IF(B17="","",IF(COUNTIF($B$5:$B17,B17)=1,MAX($O$4:$O16)+1,""))
O18: =IF(B18="","",IF(COUNTIF($B$5:$B18,B18)=1,MAX($O$4:$O17)+1,""))
O19: =IF(B19="","",IF(COUNTIF($B$5:$B19,B19)=1,MAX($O$4:$O18)+1,""))
O20: =IF(B20="","",IF(COUNTIF($B$5:$B20,B20)=1,MAX($O$4:$O19)+1,""))
O21: =IF(B21="","",IF(COUNTIF($B$5:$B21,B21)=1,MAX($O$4:$O20)+1,""))
O22: =IF(B22="","",IF(COUNTIF($B$5:$B22,B22)=1,MAX($O$4:$O21)+1,""))
... O34: =IF(B34="","",IF(COUNTIF($B$5:$B34,B34)=1,MAX($O$4:$O33)+1,""))

Sheet CASHBACK_RULES
A1: 🎯 CASHBACK_RULES — cấu hình chương trình hoàn tiền
A2: 1 dòng = 1 MCC của 1 nhóm. Cùng Card ID + Nhóm = cùng 1 cap nhóm. Cap để trống = không giới hạn. Rate nhập dạng 15%.
A3: ⚠ SAMPLE DATA — có thể xóa · ✎ ô chữ xanh = nhập liệu · ⚙ ô nền xám = tự động (không sửa)
A4: Rule ID | B4: Card ID | C4: Ngân hàng | D4: Tên thẻ | E4: Nhóm cashback | F4: Tên danh mục | G4: MCC | H4: Tên MCC | I4: Cashback Rate (%) | J4: Max Cashback / Category / Month | K4: Max Cashback / Card / Month | L4: Max Eligible Spending | M4: Minimum Transaction | N4: Start Date | O4: End Date | P4: Điều kiện | Q4: Ghi chú | R4: Kiểm tra | S4: Group # (helper)
A5: =IF(B5="","","R"&TEXT(ROW()-4,"000")) -> R001 | B5: VPB-JCBZ | C5: =IF(B5="","",IFERROR(INDEX(CARDS!$B$5:$B$34,MATCH(B5,CARDS!$A$5:$A$34,0)),"⚠ Card ID?")) -> VPBank | D5: =IF(B5="","",IFERROR(INDEX(CARDS!$C$5:$C$34,MATCH(B5,CARDS!$A$5:$A$34,0)),"⚠ Card ID?")) -> JCB Z Card | E5: Group 1 | F5: Dining | G5: 5811 | H5: =IF(G5="","",IFERROR(INDEX(MCC_MASTER!$B$5:$B$504,MATCH(G5,MCC_MASTER!$A$5:$A$504,0)),"⚠ MCC chưa có trong MCC_MASTER")) -> Caterers | I5: 0.15 | J5: 500000 | K5: 1000000 | N5: 46023 | O5: 46387 | P5: Ăn uống | Q5: SAMPLE DATA — có thể xóa | R5: =IF(B5="","",IF(ISNA(MATCH(B5,CARDS!$A$5:$A$34,0)),"⚠ Card ID không tồn tại",IF(E5="","⚠ Thiếu Nhóm cashback",IF(OR(SUMPRODUCT(($B$5:$B$304=B5)*($E$5:$E$304=E5)*($J$5:$J$304<>J5))>0,SUMPRODUCT(($B$5:$B$304=B5)*($K$5:$K$304<>K5))>0),"⚠ Cap không đồng nhất","✓ OK")))) -> ✓ OK | S5: =IF(OR(B5="",E5=""),"",IF(COUNTIFS($B$5:$B5,B5,$E$5:$E5,E5)=1,MAX($S$4:$S4)+1,"")) -> 1
A6: =IF(B6="","","R"&TEXT(ROW()-4,"000")) -> R002 | B6: VPB-JCBZ | C6: =IF(B6="","",IFERROR(INDEX(CARDS!$B$5:$B$34,MATCH(B6,CARDS!$A$5:$A$34,0)),"⚠ Card ID?")) -> VPBank | D6: =IF(B6="","",IFERROR(INDEX(CARDS!$C$5:$C$34,MATCH(B6,CARDS!$A$5:$A$34,0)),"⚠ Card ID?")) -> JCB Z Card | E6: Group 1 | F6: Dining | G6: 5812 | H6: =IF(G6="","",IFERROR(INDEX(MCC_MASTER!$B$5:$B$504,MATCH(G6,MCC_MASTER!$A$5:$A$504,0)),"⚠ MCC chưa có trong MCC_MASTER")) -> Eating Places / Restaurants | I6: 0.15 | J6: 500000 | K6: 1000000 | N6: 46023 | O6: 46387 | P6: Ăn uống | Q6: SAMPLE DATA — có thể xóa | R6: =IF(B6="","",IF(ISNA(MATCH(B6,CARDS!$A$5:$A$34,0)),"⚠ Card ID không tồn tại",IF(E6="","⚠ Thiếu Nhóm cashback",IF(OR(SUMPRODUCT(($B$5:$B$304=B6)*($E$5:$E$304=E6)*($J$5:$J$304<>J6))>0,SUMPRODUCT(($B$5:$B$304=B6)*($K$5:$K$304<>K6))>0),"⚠ Cap không đồng nhất","✓ OK")))) -> ✓ OK | S6: =IF(OR(B6="",E6=""),"",IF(COUNTIFS($B$5:$B6,B6,$E$5:$E6,E6)=1,MAX($S$4:$S5)+1,""))
A7: =IF(B7="","","R"&TEXT(ROW()-4,"000")) -> R003 | B7: VPB-JCBZ | C7: =IF(B7="","",IFERROR(INDEX(CARDS!$B$5:$B$34,MATCH(B7,CARDS!$A$5:$A$34,0)),"⚠ Card ID?")) -> VPBank | D7: =IF(B7="","",IFERROR(INDEX(CARDS!$C$5:$C$34,MATCH(B7,CARDS!$A$5:$A$34,0)),"⚠ Card ID?")) -> JCB Z Card | E7: Group 1 | F7: Dining | G7: 5813 | H7: =IF(G7="","",IFERROR(INDEX(MCC_MASTER!$B$5:$B$504,MATCH(G7,MCC_MASTER!$A$5:$A$504,0)),"⚠ MCC chưa có trong MCC_MASTER")) -> Drinking Places (Bars, Taverns) | I7: 0.15 | J7: 500000 | K7: 1000000 | N7: 46023 | O7: 46387 | P7: Ăn uống | Q7: SAMPLE DATA — có thể xóa | R7: =IF(B7="","",IF(ISNA(MATCH(B7,CARDS!$A$5:$A$34,0)),"⚠ Card ID không tồn tại",IF(E7="","⚠ Thiếu Nhóm cashback",IF(OR(SUMPRODUCT(($B$5:$B$304=B7)*($E$5:$E$304=E7)*($J$5:$J$304<>J7))>0,SUMPRODUCT(($B$5:$B$304=B7)*($K$5:$K$304<>K7))>0),"⚠ Cap không đồng nhất","✓ OK")))) -> ✓ OK | S7: =IF(OR(B7="",E7=""),"",IF(COUNTIFS($B$5:$B7,B7,$E$5:$E7,E7)=1,MAX($S$4:$S6)+1,""))
A8: =IF(B8="","","R"&TEXT(ROW()-4,"000")) -> R004 | B8: VPB-JCBZ | C8: =IF(B8="","",IFERROR(INDEX(CARDS!$B$5:$B$34,MATCH(B8,CARDS!$A$5:$A$34,0)),"⚠ Card ID?")) -> VPBank | D8: =IF(B8="","",IFERROR(INDEX(CARDS!$C$5:$C$34,MATCH(B8,CARDS!$A$5:$A$34,0)),"⚠ Card ID?")) -> JCB Z Card | E8: Group 1 | F8: Dining | G8: 5814 | H8: =IF(G8="","",IFERROR(INDEX(MCC_MASTER!$B$5:$B$504,MATCH(G8,MCC_MASTER!$A$5:$A$504,0)),"⚠ MCC chưa có trong MCC_MASTER")) -> Fast Food Restaurants | I8: 0.15 | J8: 500000 | K8: 1000000 | N8: 46023 | O8: 46387 | P8: Ăn uống | Q8: SAMPLE DATA — có thể xóa | R8: =IF(B8="","",IF(ISNA(MATCH(B8,CARDS!$A$5:$A$34,0)),"⚠ Card ID không tồn tại",IF(E8="","⚠ Thiếu Nhóm cashback",IF(OR(SUMPRODUCT(($B$5:$B$304=B8)*($E$5:$E$304=E8)*($J$5:$J$304<>J8))>0,SUMPRODUCT(($B$5:$B$304=B8)*($K$5:$K$304<>K8))>0),"⚠ Cap không đồng nhất","✓ OK")))) -> ✓ OK | S8: =IF(OR(B8="",E8=""),"",IF(COUNTIFS($B$5:$B8,B8,$E$5:$E8,E8)=1,MAX($S$4:$S7)+1,""))
A9: =IF(B9="","","R"&TEXT(ROW()-4,"000")) -> R005 | B9: VPB-JCBZ | C9: =IF(B9="","",IFERROR(INDEX(CARDS!$B$5:$B$34,MATCH(B9,CARDS!$A$5:$A$34,0)),"⚠ Card ID?")) -> VPBank | D9: =IF(B9="","",IFERROR(INDEX(CARDS!$C$5:$C$34,MATCH(B9,CARDS!$A$5:$A$34,0)),"⚠ Card ID?")) -> JCB Z Card | E9: Group 2 | F9: Entertainment / Fitness | G9: 5734 | H9: =IF(G9="","",IFERROR(INDEX(MCC_MASTER!$B$5:$B$504,MATCH(G9,MCC_MASTER!$A$5:$A$504,0)),"⚠ MCC chưa có trong MCC_MASTER")) -> Computer Software Stores | I9: 0.15 | J9: 500000 | K9: 1000000 | N9: 46023 | O9: 46387 | P9: Giải trí / Fitness | Q9: SAMPLE DATA — có thể xóa | R9: =IF(B9="","",IF(ISNA(MATCH(B9,CARDS!$A$5:$A$34,0)),"⚠ Card ID không tồn tại",IF(E9="","⚠ Thiếu Nhóm cashback",IF(OR(SUMPRODUCT(($B$5:$B$304=B9)*($E$5:$E$304=E9)*($J$5:$J$304<>J9))>0,SUMPRODUCT(($B$5:$B$304=B9)*($K$5:$K$304<>K9))>0),"⚠ Cap không đồng nhất","✓ OK")))) -> ✓ OK | S9: =IF(OR(B9="",E9=""),"",IF(COUNTIFS($B$5:$B9,B9,$E$5:$E9,E9)=1,MAX($S$4:$S8)+1,"")) -> 2
A10: =IF(B10="","","R"&TEXT(ROW()-4,"000")) -> R006 | B10: VPB-JCBZ | C10: =IF(B10="","",IFERROR(INDEX(CARDS!$B$5:$B$34,MATCH(B10,CARDS!$A$5:$A$34,0)),"⚠ Card ID?")) -> VPBank | D10: =IF(B10="","",IFERROR(INDEX(CARDS!$C$5:$C$34,MATCH(B10,CARDS!$A$5:$A$34,0)),"⚠ Card ID?")) -> JCB Z Card | E10: Group 2 | F10: Entertainment / Fitness | G10: 5735 | H10: =IF(G10="","",IFERROR(INDEX(MCC_MASTER!$B$5:$B$504,MATCH(G10,MCC_MASTER!$A$5:$A$504,0)),"⚠ MCC chưa có trong MCC_MASTER")) -> Record Stores | I10: 0.15 | J10: 500000 | K10: 1000000 | N10: 46023 | O10: 46387 | P10: Giải trí / Fitness | Q10: SAMPLE DATA — có thể xóa | R10: =IF(B10="","",IF(ISNA(MATCH(B10,CARDS!$A$5:$A$34,0)),"⚠ Card ID không tồn tại",IF(E10="","⚠ Thiếu Nhóm cashback",IF(OR(SUMPRODUCT(($B$5:$B$304=B10)*($E$5:$E$304=E10)*($J$5:$J$304<>J10))>0,SUMPRODUCT(($B$5:$B$304=B10)*($K$5:$K$304<>K10))>0),"⚠ Cap không đồng nhất","✓ OK")))) -> ✓ OK | S10: =IF(OR(B10="",E10=""),"",IF(COUNTIFS($B$5:$B10,B10,$E$5:$E10,E10)=1,MAX($S$4:$S9)+1,""))
A11: =IF(B11="","","R"&TEXT(ROW()-4,"000")) -> R007 | B11: VPB-JCBZ | C11: =IF(B11="","",IFERROR(INDEX(CARDS!$B$5:$B$34,MATCH(B11,CARDS!$A$5:$A$34,0)),"⚠ Card ID?")) -> VPBank | D11: =IF(B11="","",IFERROR(INDEX(CARDS!$C$5:$C$34,MATCH(B11,CARDS!$A$5:$A$34,0)),"⚠ Card ID?")) -> JCB Z Card | E11: Group 2 | F11: Entertainment / Fitness | G11: 7832 | H11: =IF(G11="","",IFERROR(INDEX(MCC_MASTER!$B$5:$B$504,MATCH(G11,MCC_MASTER!$A$5:$A$504,0)),"⚠ MCC chưa có trong MCC_MASTER")) -> Motion Picture Theaters | I11: 0.15 | J11: 500000 | K11: 1000000 | N11: 46023 | O11: 46387 | P11: Giải trí / Fitness | Q11: SAMPLE DATA — có thể xóa | R11: =IF(B11="","",IF(ISNA(MATCH(B11,CARDS!$A$5:$A$34,0)),"⚠ Card ID không tồn tại",IF(E11="","⚠ Thiếu Nhóm cashback",IF(OR(SUMPRODUCT(($B$5:$B$304=B11)*($E$5:$E$304=E11)*($J$5:$J$304<>J11))>0,SUMPRODUCT(($B$5:$B$304=B11)*($K$5:$K$304<>K11))>0),"⚠ Cap không đồng nhất","✓ OK")))) -> ✓ OK | S11: =IF(OR(B11="",E11=""),"",IF(COUNTIFS($B$5:$B11,B11,$E$5:$E11,E11)=1,MAX($S$4:$S10)+1,""))
A12: =IF(B12="","","R"&TEXT(ROW()-4,"000")) -> R008 | B12: VPB-JCBZ | C12: =IF(B12="","",IFERROR(INDEX(CARDS!$B$5:$B$34,MATCH(B12,CARDS!$A$5:$A$34,0)),"⚠ Card ID?")) -> VPBank | D12: =IF(B12="","",IFERROR(INDEX(CARDS!$C$5:$C$34,MATCH(B12,CARDS!$A$5:$A$34,0)),"⚠ Card ID?")) -> JCB Z Card | E12: Group 2 | F12: Entertainment / Fitness | G12: 7997 | H12: =IF(G12="","",IFERROR(INDEX(MCC_MASTER!$B$5:$B$504,MATCH(G12,MCC_MASTER!$A$5:$A$504,0)),"⚠ MCC chưa có trong MCC_MASTER")) -> Membership Clubs (Sports / Recreation) | I12: 0.15 | J12: 500000 | K12: 1000000 | N12: 46023 | O12: 46387 | P12: Giải trí / Fitness | Q12: SAMPLE DATA — có thể xóa | R12: =IF(B12="","",IF(ISNA(MATCH(B12,CARDS!$A$5:$A$34,0)),"⚠ Card ID không tồn tại",IF(E12="","⚠ Thiếu Nhóm cashback",IF(OR(SUMPRODUCT(($B$5:$B$304=B12)*($E$5:$E$304=E12)*($J$5:$J$304<>J12))>0,SUMPRODUCT(($B$5:$B$304=B12)*($K$5:$K$304<>K12))>0),"⚠ Cap không đồng nhất","✓ OK")))) -> ✓ OK | S12: =IF(OR(B12="",E12=""),"",IF(COUNTIFS($B$5:$B12,B12,$E$5:$E12,E12)=1,MAX($S$4:$S11)+1,""))
A13: =IF(B13="","","R"&TEXT(ROW()-4,"000")) -> R009 | B13: VPB-JCBZ | C13: =IF(B13="","",IFERROR(INDEX(CARDS!$B$5:$B$34,MATCH(B13,CARDS!$A$5:$A$34,0)),"⚠ Card ID?")) -> VPBank | D13: =IF(B13="","",IFERROR(INDEX(CARDS!$C$5:$C$34,MATCH(B13,CARDS!$A$5:$A$34,0)),"⚠ Card ID?")) -> JCB Z Card | E13: Group 3 | F13: Transport / Food Delivery | G13: 4121 | H13: =IF(G13="","",IFERROR(INDEX(MCC_MASTER!$B$5:$B$504,MATCH(G13,MCC_MASTER!$A$5:$A$504,0)),"⚠ MCC chưa có trong MCC_MASTER")) -> Taxicabs / Limousines | I13: 0.15 | J13: 500000 | K13: 1000000 | N13: 46023 | O13: 46387 | P13: Di chuyển / giao đồ ăn (5814 trùng Nhóm 1 → chọn Rule ID để vào nhóm này) | Q13: SAMPLE DATA — có thể xóa | R13: =IF(B13="","",IF(ISNA(MATCH(B13,CARDS!$A$5:$A$34,0)),"⚠ Card ID không tồn tại",IF(E13="","⚠ Thiếu Nhóm cashback",IF(OR(SUMPRODUCT(($B$5:$B$304=B13)*($E$5:$E$304=E13)*($J$5:$J$304<>J13))>0,SUMPRODUCT(($B$5:$B$304=B13)*($K$5:$K$304<>K13))>0),"⚠ Cap không đồng nhất","✓ OK")))) -> ✓ OK | S13: =IF(OR(B13="",E13=""),"",IF(COUNTIFS($B$5:$B13,B13,$E$5:$E13,E13)=1,MAX($S$4:$S12)+1,"")) -> 3
A14: =IF(B14="","","R"&TEXT(ROW()-4,"000")) -> R010 | B14: VPB-JCBZ | C14: =IF(B14="","",IFERROR(INDEX(CARDS!$B$5:$B$34,MATCH(B14,CARDS!$A$5:$A$34,0)),"⚠ Card ID?")) -> VPBank | D14: =IF(B14="","",IFERROR(INDEX(CARDS!$C$5:$C$34,MATCH(B14,CARDS!$A$5:$A$34,0)),"⚠ Card ID?")) -> JCB Z Card | E14: Group 3 | F14: Transport / Food Delivery | G14: 5814 | H14: =IF(G14="","",IFERROR(INDEX(MCC_MASTER!$B$5:$B$504,MATCH(G14,MCC_MASTER!$A$5:$A$504,0)),"⚠ MCC chưa có trong MCC_MASTER")) -> Fast Food Restaurants | I14: 0.15 | J14: 500000 | K14: 1000000 | N14: 46023 | O14: 46387 | P14: Di chuyển / giao đồ ăn (5814 trùng Nhóm 1 → chọn Rule ID để vào nhóm này) | Q14: SAMPLE DATA — có thể xóa | R14: =IF(B14="","",IF(ISNA(MATCH(B14,CARDS!$A$5:$A$34,0)),"⚠ Card ID không tồn tại",IF(E14="","⚠ Thiếu Nhóm cashback",IF(OR(SUMPRODUCT(($B$5:$B$304=B14)*($E$5:$E$304=E14)*($J$5:$J$304<>J14))>0,SUMPRODUCT(($B$5:$B$304=B14)*($K$5:$K$304<>K14))>0),"⚠ Cap không đồng nhất","✓ OK")))) -> ✓ OK | S14: =IF(OR(B14="",E14=""),"",IF(COUNTIFS($B$5:$B14,B14,$E$5:$E14,E14)=1,MAX($S$4:$S13)+1,""))
A15: =IF(B15="","","R"&TEXT(ROW()-4,"000")) -> R011 | B15: VIB-A | C15: =IF(B15="","",IFERROR(INDEX(CARDS!$B$5:$B$34,MATCH(B15,CARDS!$A$5:$A$34,0)),"⚠ Card ID?")) -> VIB | D15: =IF(B15="","",IFERROR(INDEX(CARDS!$C$5:$C$34,MATCH(B15,CARDS!$A$5:$A$34,0)),"⚠ Card ID?")) -> Cashback Demo A | E15: Group 1 | F15: Groceries | G15: 5411 | H15: =IF(G15="","",IFERROR(INDEX(MCC_MASTER!$B$5:$B$504,MATCH(G15,MCC_MASTER!$A$5:$A$504,0)),"⚠ MCC chưa có trong MCC_MASTER")) -> Grocery Stores / Supermarkets | I15: 0.1 | J15: 500000 | K15: 1000000 | Q15: SAMPLE DATA — có thể xóa | R15: =IF(B15="","",IF(ISNA(MATCH(B15,CARDS!$A$5:$A$34,0)),"⚠ Card ID không tồn tại",IF(E15="","⚠ Thiếu Nhóm cashback",IF(OR(SUMPRODUCT(($B$5:$B$304=B15)*($E$5:$E$304=E15)*($J$5:$J$304<>J15))>0,SUMPRODUCT(($B$5:$B$304=B15)*($K$5:$K$304<>K15))>0),"⚠ Cap không đồng nhất","✓ OK")))) -> ✓ OK | S15: =IF(OR(B15="",E15=""),"",IF(COUNTIFS($B$5:$B15,B15,$E$5:$E15,E15)=1,MAX($S$4:$S14)+1,"")) -> 4
A16: =IF(B16="","","R"&TEXT(ROW()-4,"000")) -> R012 | B16: VIB-A | C16: =IF(B16="","",IFERROR(INDEX(CARDS!$B$5:$B$34,MATCH(B16,CARDS!$A$5:$A$34,0)),"⚠ Card ID?")) -> VIB | D16: =IF(B16="","",IFERROR(INDEX(CARDS!$C$5:$C$34,MATCH(B16,CARDS!$A$5:$A$34,0)),"⚠ Card ID?")) -> Cashback Demo A | E16: Group 1 | F16: Groceries | G16: 5499 | H16: =IF(G16="","",IFERROR(INDEX(MCC_MASTER!$B$5:$B$504,MATCH(G16,MCC_MASTER!$A$5:$A$504,0)),"⚠ MCC chưa có trong MCC_MASTER")) -> Misc. Food Stores – Convenience | I16: 0.1 | J16: 500000 | K16: 1000000 | Q16: SAMPLE DATA — có thể xóa | R16: =IF(B16="","",IF(ISNA(MATCH(B16,CARDS!$A$5:$A$34,0)),"⚠ Card ID không tồn tại",IF(E16="","⚠ Thiếu Nhóm cashback",IF(OR(SUMPRODUCT(($B$5:$B$304=B16)*($E$5:$E$304=E16)*($J$5:$J$304<>J16))>0,SUMPRODUCT(($B$5:$B$304=B16)*($K$5:$K$304<>K16))>0),"⚠ Cap không đồng nhất","✓ OK")))) -> ✓ OK | S16: =IF(OR(B16="",E16=""),"",IF(COUNTIFS($B$5:$B16,B16,$E$5:$E16,E16)=1,MAX($S$4:$S15)+1,""))
A17: =IF(B17="","","R"&TEXT(ROW()-4,"000")) -> R013 | B17: VIB-A | C17: =IF(B17="","",IFERROR(INDEX(CARDS!$B$5:$B$34,MATCH(B17,CARDS!$A$5:$A$34,0)),"⚠ Card ID?")) -> VIB | D17: =IF(B17="","",IFERROR(INDEX(CARDS!$C$5:$C$34,MATCH(B17,CARDS!$A$5:$A$34,0)),"⚠ Card ID?")) -> Cashback Demo A | E17: Group 2 | F17: Shopping | G17: 5311 | H17: =IF(G17="","",IFERROR(INDEX(MCC_MASTER!$B$5:$B$504,MATCH(G17,MCC_MASTER!$A$5:$A$504,0)),"⚠ MCC chưa có trong MCC_MASTER")) -> Department Stores | I17: 0.1 | J17: 500000 | K17: 1000000 | Q17: SAMPLE DATA — có thể xóa | R17: =IF(B17="","",IF(ISNA(MATCH(B17,CARDS!$A$5:$A$34,0)),"⚠ Card ID không tồn tại",IF(E17="","⚠ Thiếu Nhóm cashback",IF(OR(SUMPRODUCT(($B$5:$B$304=B17)*($E$5:$E$304=E17)*($J$5:$J$304<>J17))>0,SUMPRODUCT(($B$5:$B$304=B17)*($K$5:$K$304<>K17))>0),"⚠ Cap không đồng nhất","✓ OK")))) -> ✓ OK | S17: =IF(OR(B17="",E17=""),"",IF(COUNTIFS($B$5:$B17,B17,$E$5:$E17,E17)=1,MAX($S$4:$S16)+1,"")) -> 5
A18: =IF(B18="","","R"&TEXT(ROW()-4,"000")) -> R014 | B18: VIB-A | C18: =IF(B18="","",IFERROR(INDEX(CARDS!$B$5:$B$34,MATCH(B18,CARDS!$A$5:$A$34,0)),"⚠ Card ID?")) -> VIB | D18: =IF(B18="","",IFERROR(INDEX(CARDS!$C$5:$C$34,MATCH(B18,CARDS!$A$5:$A$34,0)),"⚠ Card ID?")) -> Cashback Demo A | E18: Group 2 | F18: Shopping | G18: 5399 | H18: =IF(G18="","",IFERROR(INDEX(MCC_MASTER!$B$5:$B$504,MATCH(G18,MCC_MASTER!$A$5:$A$504,0)),"⚠ MCC chưa có trong MCC_MASTER")) -> Misc. General Merchandise | I18: 0.1 | J18: 500000 | K18: 1000000 | Q18: SAMPLE DATA — có thể xóa | R18: =IF(B18="","",IF(ISNA(MATCH(B18,CARDS!$A$5:$A$34,0)),"⚠ Card ID không tồn tại",IF(E18="","⚠ Thiếu Nhóm cashback",IF(OR(SUMPRODUCT(($B$5:$B$304=B18)*($E$5:$E$304=E18)*($J$5:$J$304<>J18))>0,SUMPRODUCT(($B$5:$B$304=B18)*($K$5:$K$304<>K18))>0),"⚠ Cap không đồng nhất","✓ OK")))) -> ✓ OK | S18: =IF(OR(B18="",E18=""),"",IF(COUNTIFS($B$5:$B18,B18,$E$5:$E18,E18)=1,MAX($S$4:$S17)+1,""))
A19: =IF(B19="","","R"&TEXT(ROW()-4,"000")) -> R015 | B19: TCB-B | C19: =IF(B19="","",IFERROR(INDEX(CARDS!$B$5:$B$34,MATCH(B19,CARDS!$A$5:$A$34,0)),"⚠ Card ID?")) -> Techcombank | D19: =IF(B19="","",IFERROR(INDEX(CARDS!$C$5:$C$34,MATCH(B19,CARDS!$A$5:$A$34,0)),"⚠ Card ID?")) -> Cashback Demo B | E19: Group 1 | F19: Fuel & Transport | G19: 5541 | H19: =IF(G19="","",IFERROR(INDEX(MCC_MASTER!$B$5:$B$504,MATCH(G19,MCC_MASTER!$A$5:$A$504,0)),"⚠ MCC chưa có trong MCC_MASTER")) -> Service Stations | I19: 0.05 | J19: 300000 | K19: 2000000 | Q19: SAMPLE DATA — có thể xóa | R19: =IF(B19="","",IF(ISNA(MATCH(B19,CARDS!$A$5:$A$34,0)),"⚠ Card ID không tồn tại",IF(E19="","⚠ Thiếu Nhóm cashback",IF(OR(SUMPRODUCT(($B$5:$B$304=B19)*($E$5:$E$304=E19)*($J$5:$J$304<>J19))>0,SUMPRODUCT(($B$5:$B$304=B19)*($K$5:$K$304<>K19))>0),"⚠ Cap không đồng nhất","✓ OK")))) -> ✓ OK | S19: =IF(OR(B19="",E19=""),"",IF(COUNTIFS($B$5:$B19,B19,$E$5:$E19,E19)=1,MAX($S$4:$S18)+1,"")) -> 6
A20: =IF(B20="","","R"&TEXT(ROW()-4,"000")) -> R016 | B20: TCB-B | C20: =IF(B20="","",IFERROR(INDEX(CARDS!$B$5:$B$34,MATCH(B20,CARDS!$A$5:$A$34,0)),"⚠ Card ID?")) -> Techcombank | D20: =IF(B20="","",IFERROR(INDEX(CARDS!$C$5:$C$34,MATCH(B20,CARDS!$A$5:$A$34,0)),"⚠ Card ID?")) -> Cashback Demo B | E20: Group 1 | F20: Fuel & Transport | G20: 5542 | H20: =IF(G20="","",IFERROR(INDEX(MCC_MASTER!$B$5:$B$504,MATCH(G20,MCC_MASTER!$A$5:$A$504,0)),"⚠ MCC chưa có trong MCC_MASTER")) -> Automated Fuel Dispensers | I20: 0.05 | J20: 300000 | K20: 2000000 | Q20: SAMPLE DATA — có thể xóa | R20: =IF(B20="","",IF(ISNA(MATCH(B20,CARDS!$A$5:$A$34,0)),"⚠ Card ID không tồn tại",IF(E20="","⚠ Thiếu Nhóm cashback",IF(OR(SUMPRODUCT(($B$5:$B$304=B20)*($E$5:$E$304=E20)*($J$5:$J$304<>J20))>0,SUMPRODUCT(($B$5:$B$304=B20)*($K$5:$K$304<>K20))>0),"⚠ Cap không đồng nhất","✓ OK")))) -> ✓ OK | S20: =IF(OR(B20="",E20=""),"",IF(COUNTIFS($B$5:$B20,B20,$E$5:$E20,E20)=1,MAX($S$4:$S19)+1,""))
A21: =IF(B21="","","R"&TEXT(ROW()-4,"000")) -> R017 | B21: TCB-B | C21: =IF(B21="","",IFERROR(INDEX(CARDS!$B$5:$B$34,MATCH(B21,CARDS!$A$5:$A$34,0)),"⚠ Card ID?")) -> Techcombank | D21: =IF(B21="","",IFERROR(INDEX(CARDS!$C$5:$C$34,MATCH(B21,CARDS!$A$5:$A$34,0)),"⚠ Card ID?")) -> Cashback Demo B | E21: Group 1 | F21: Fuel & Transport | G21: 4121 | H21: =IF(G21="","",IFERROR(INDEX(MCC_MASTER!$B$5:$B$504,MATCH(G21,MCC_MASTER!$A$5:$A$504,0)),"⚠ MCC chưa có trong MCC_MASTER")) -> Taxicabs / Limousines | I21: 0.05 | J21: 300000 | K21: 2000000 | Q21: SAMPLE DATA — có thể xóa | R21: =IF(B21="","",IF(ISNA(MATCH(B21,CARDS!$A$5:$A$34,0)),"⚠ Card ID không tồn tại",IF(E21="","⚠ Thiếu Nhóm cashback",IF(OR(SUMPRODUCT(($B$5:$B$304=B21)*($E$5:$E$304=E21)*($J$5:$J$304<>J21))>0,SUMPRODUCT(($B$5:$B$304=B21)*($K$5:$K$304<>K21))>0),"⚠ Cap không đồng nhất","✓ OK")))) -> ✓ OK | S21: =IF(OR(B21="",E21=""),"",IF(COUNTIFS($B$5:$B21,B21,$E$5:$E21,E21)=1,MAX($S$4:$S20)+1,""))
A22: =IF(B22="","","R"&TEXT(ROW()-4,"000")) -> R018 | B22: TCB-B | C22: =IF(B22="","",IFERROR(INDEX(CARDS!$B$5:$B$34,MATCH(B22,CARDS!$A$5:$A$34,0)),"⚠ Card ID?")) -> Techcombank | D22: =IF(B22="","",IFERROR(INDEX(CARDS!$C$5:$C$34,MATCH(B22,CARDS!$A$5:$A$34,0)),"⚠ Card ID?")) -> Cashback Demo B | E22: Group 2 | F22: Healthcare | G22: 8011 | H22: =IF(G22="","",IFERROR(INDEX(MCC_MASTER!$B$5:$B$504,MATCH(G22,MCC_MASTER!$A$5:$A$504,0)),"⚠ MCC chưa có trong MCC_MASTER")) -> Doctors | I22: 0.05 | J22: 300000 | K22: 2000000 | Q22: SAMPLE DATA — có thể xóa | R22: =IF(B22="","",IF(ISNA(MATCH(B22,CARDS!$A$5:$A$34,0)),"⚠ Card ID không tồn tại",IF(E22="","⚠ Thiếu Nhóm cashback",IF(OR(SUMPRODUCT(($B$5:$B$304=B22)*($E$5:$E$304=E22)*($J$5:$J$304<>J22))>0,SUMPRODUCT(($B$5:$B$304=B22)*($K$5:$K$304<>K22))>0),"⚠ Cap không đồng nhất","✓ OK")))) -> ✓ OK | S22: =IF(OR(B22="",E22=""),"",IF(COUNTIFS($B$5:$B22,B22,$E$5:$E22,E22)=1,MAX($S$4:$S21)+1,"")) -> 7
A23: =IF(B23="","","R"&TEXT(ROW()-4,"000")) -> R019 | B23: TCB-B | C23: =IF(B23="","",IFERROR(INDEX(CARDS!$B$5:$B$34,MATCH(B23,CARDS!$A$5:$A$34,0)),"⚠ Card ID?")) -> Techcombank | D23: =IF(B23="","",IFERROR(INDEX(CARDS!$C$5:$C$34,MATCH(B23,CARDS!$A$5:$A$34,0)),"⚠ Card ID?")) -> Cashback Demo B | E23: Group 2 | F23: Healthcare | G23: 8062 | H23: =IF(G23="","",IFERROR(INDEX(MCC_MASTER!$B$5:$B$504,MATCH(G23,MCC_MASTER!$A$5:$A$504,0)),"⚠ MCC chưa có trong MCC_MASTER")) -> Hospitals | I23: 0.05 | J23: 300000 | K23: 2000000 | Q23: SAMPLE DATA — có thể xóa | R23: =IF(B23="","",IF(ISNA(MATCH(B23,CARDS!$A$5:$A$34,0)),"⚠ Card ID không tồn tại",IF(E23="","⚠ Thiếu Nhóm cashback",IF(OR(SUMPRODUCT(($B$5:$B$304=B23)*($E$5:$E$304=E23)*($J$5:$J$304<>J23))>0,SUMPRODUCT(($B$5:$B$304=B23)*($K$5:$K$304<>K23))>0),"⚠ Cap không đồng nhất","✓ OK")))) -> ✓ OK | S23: =IF(OR(B23="",E23=""),"",IF(COUNTIFS($B$5:$B23,B23,$E$5:$E23,E23)=1,MAX($S$4:$S22)+1,""))
A24: =IF(B24="","","R"&TEXT(ROW()-4,"000")) -> R020 | B24: TCB-B | C24: =IF(B24="","",IFERROR(INDEX(CARDS!$B$5:$B$34,MATCH(B24,CARDS!$A$5:$A$34,0)),"⚠ Card ID?")) -> Techcombank | D24: =IF(B24="","",IFERROR(INDEX(CARDS!$C$5:$C$34,MATCH(B24,CARDS!$A$5:$A$34,0)),"⚠ Card ID?")) -> Cashback Demo B | E24: Group 3 | F24: Utilities & Telecom | G24: 4814 | H24: =IF(G24="","",IFERROR(INDEX(MCC_MASTER!$B$5:$B$504,MATCH(G24,MCC_MASTER!$A$5:$A$504,0)),"⚠ MCC chưa có trong MCC_MASTER")) -> Telecommunication Services | I24: 0.05 | J24: 300000 | K24: 2000000 | Q24: SAMPLE DATA — có thể xóa | R24: =IF(B24="","",IF(ISNA(MATCH(B24,CARDS!$A$5:$A$34,0)),"⚠ Card ID không tồn tại",IF(E24="","⚠ Thiếu Nhóm cashback",IF(OR(SUMPRODUCT(($B$5:$B$304=B24)*($E$5:$E$304=E24)*($J$5:$J$304<>J24))>0,SUMPRODUCT(($B$5:$B$304=B24)*($K$5:$K$304<>K24))>0),"⚠ Cap không đồng nhất","✓ OK")))) -> ✓ OK | S24: =IF(OR(B24="",E24=""),"",IF(COUNTIFS($B$5:$B24,B24,$E$5:$E24,E24)=1,MAX($S$4:$S23)+1,"")) -> 8
A25: =IF(B25="","","R"&TEXT(ROW()-4,"000")) -> R021 | B25: TCB-B | C25: =IF(B25="","",IFERROR(INDEX(CARDS!$B$5:$B$34,MATCH(B25,CARDS!$A$5:$A$34,0)),"⚠ Card ID?")) -> Techcombank | D25: =IF(B25="","",IFERROR(INDEX(CARDS!$C$5:$C$34,MATCH(B25,CARDS!$A$5:$A$34,0)),"⚠ Card ID?")) -> Cashback Demo B | E25: Group 3 | F25: Utilities & Telecom | G25: 4900 | H25: =IF(G25="","",IFERROR(INDEX(MCC_MASTER!$B$5:$B$504,MATCH(G25,MCC_MASTER!$A$5:$A$504,0)),"⚠ MCC chưa có trong MCC_MASTER")) -> Utilities – Electric, Gas, Water, Sanitary | I25: 0.05 | J25: 300000 | K25: 2000000 | Q25: SAMPLE DATA — có thể xóa | R25: =IF(B25="","",IF(ISNA(MATCH(B25,CARDS!$A$5:$A$34,0)),"⚠ Card ID không tồn tại",IF(E25="","⚠ Thiếu Nhóm cashback",IF(OR(SUMPRODUCT(($B$5:$B$304=B25)*($E$5:$E$304=E25)*($J$5:$J$304<>J25))>0,SUMPRODUCT(($B$5:$B$304=B25)*($K$5:$K$304<>K25))>0),"⚠ Cap không đồng nhất","✓ OK")))) -> ✓ OK | S25: =IF(OR(B25="",E25=""),"",IF(COUNTIFS($B$5:$B25,B25,$E$5:$E25,E25)=1,MAX($S$4:$S24)+1,""))
A26: =IF(B26="","","R"&TEXT(ROW()-4,"000")) -> R022 | B26: UOB-C | C26: =IF(B26="","",IFERROR(INDEX(CARDS!$B$5:$B$34,MATCH(B26,CARDS!$A$5:$A$34,0)),"⚠ Card ID?")) -> UOB | D26: =IF(B26="","",IFERROR(INDEX(CARDS!$C$5:$C$34,MATCH(B26,CARDS!$A$5:$A$34,0)),"⚠ Card ID?")) -> Cashback Demo C | E26: Group 1 | F26: Dining | G26: 5812 | H26: =IF(G26="","",IFERROR(INDEX(MCC_MASTER!$B$5:$B$504,MATCH(G26,MCC_MASTER!$A$5:$A$504,0)),"⚠ MCC chưa có trong MCC_MASTER")) -> Eating Places / Restaurants | I26: 0.15 | J26: 1000000 | Q26: SAMPLE DATA — có thể xóa | R26: =IF(B26="","",IF(ISNA(MATCH(B26,CARDS!$A$5:$A$34,0)),"⚠ Card ID không tồn tại",IF(E26="","⚠ Thiếu Nhóm cashback",IF(OR(SUMPRODUCT(($B$5:$B$304=B26)*($E$5:$E$304=E26)*($J$5:$J$304<>J26))>0,SUMPRODUCT(($B$5:$B$304=B26)*($K$5:$K$304<>K26))>0),"⚠ Cap không đồng nhất","✓ OK")))) -> ✓ OK | S26: =IF(OR(B26="",E26=""),"",IF(COUNTIFS($B$5:$B26,B26,$E$5:$E26,E26)=1,MAX($S$4:$S25)+1,"")) -> 9
A27: =IF(B27="","","R"&TEXT(ROW()-4,"000")) -> R023 | B27: UOB-C | C27: =IF(B27="","",IFERROR(INDEX(CARDS!$B$5:$B$34,MATCH(B27,CARDS!$A$5:$A$34,0)),"⚠ Card ID?")) -> UOB | D27: =IF(B27="","",IFERROR(INDEX(CARDS!$C$5:$C$34,MATCH(B27,CARDS!$A$5:$A$34,0)),"⚠ Card ID?")) -> Cashback Demo C | E27: Group 1 | F27: Dining | G27: 5814 | H27: =IF(G27="","",IFERROR(INDEX(MCC_MASTER!$B$5:$B$504,MATCH(G27,MCC_MASTER!$A$5:$A$504,0)),"⚠ MCC chưa có trong MCC_MASTER")) -> Fast Food Restaurants | I27: 0.15 | J27: 1000000 | Q27: SAMPLE DATA — có thể xóa | R27: =IF(B27="","",IF(ISNA(MATCH(B27,CARDS!$A$5:$A$34,0)),"⚠ Card ID không tồn tại",IF(E27="","⚠ Thiếu Nhóm cashback",IF(OR(SUMPRODUCT(($B$5:$B$304=B27)*($E$5:$E$304=E27)*($J$5:$J$304<>J27))>0,SUMPRODUCT(($B$5:$B$304=B27)*($K$5:$K$304<>K27))>0),"⚠ Cap không đồng nhất","✓ OK")))) -> ✓ OK | S27: =IF(OR(B27="",E27=""),"",IF(COUNTIFS($B$5:$B27,B27,$E$5:$E27,E27)=1,MAX($S$4:$S26)+1,""))
A28: =IF(B28="","","R"&TEXT(ROW()-4,"000")) -> R024 | B28: MB-D | C28: =IF(B28="","",IFERROR(INDEX(CARDS!$B$5:$B$34,MATCH(B28,CARDS!$A$5:$A$34,0)),"⚠ Card ID?")) -> MB | D28: =IF(B28="","",IFERROR(INDEX(CARDS!$C$5:$C$34,MATCH(B28,CARDS!$A$5:$A$34,0)),"⚠ Card ID?")) -> Cashback Demo D | E28: Dining | F28: Dining | G28: 5812 | H28: =IF(G28="","",IFERROR(INDEX(MCC_MASTER!$B$5:$B$504,MATCH(G28,MCC_MASTER!$A$5:$A$504,0)),"⚠ MCC chưa có trong MCC_MASTER")) -> Eating Places / Restaurants | I28: 0.08 | J28: 500000 | K28: 600000 | L28: 5000000 | P28: Tối đa 5.000.000 chi tiêu tính cashback / tháng | Q28: SAMPLE DATA — có thể xóa | R28: =IF(B28="","",IF(ISNA(MATCH(B28,CARDS!$A$5:$A$34,0)),"⚠ Card ID không tồn tại",IF(E28="","⚠ Thiếu Nhóm cashback",IF(OR(SUMPRODUCT(($B$5:$B$304=B28)*($E$5:$E$304=E28)*($J$5:$J$304<>J28))>0,SUMPRODUCT(($B$5:$B$304=B28)*($K$5:$K$304<>K28))>0),"⚠ Cap không đồng nhất","✓ OK")))) -> ✓ OK | S28: =IF(OR(B28="",E28=""),"",IF(COUNTIFS($B$5:$B28,B28,$E$5:$E28,E28)=1,MAX($S$4:$S27)+1,"")) -> 10
A29: =IF(B29="","","R"&TEXT(ROW()-4,"000")) -> R025 | B29: MB-D | C29: =IF(B29="","",IFERROR(INDEX(CARDS!$B$5:$B$34,MATCH(B29,CARDS!$A$5:$A$34,0)),"⚠ Card ID?")) -> MB | D29: =IF(B29="","",IFERROR(INDEX(CARDS!$C$5:$C$34,MATCH(B29,CARDS!$A$5:$A$34,0)),"⚠ Card ID?")) -> Cashback Demo D | E29: Fuel | F29: Fuel | G29: 5541 | H29: =IF(G29="","",IFERROR(INDEX(MCC_MASTER!$B$5:$B$504,MATCH(G29,MCC_MASTER!$A$5:$A$504,0)),"⚠ MCC chưa có trong MCC_MASTER")) -> Service Stations | I29: 0.03 | J29: 200000 | K29: 600000 | Q29: SAMPLE DATA — có thể xóa | R29: =IF(B29="","",IF(ISNA(MATCH(B29,CARDS!$A$5:$A$34,0)),"⚠ Card ID không tồn tại",IF(E29="","⚠ Thiếu Nhóm cashback",IF(OR(SUMPRODUCT(($B$5:$B$304=B29)*($E$5:$E$304=E29)*($J$5:$J$304<>J29))>0,SUMPRODUCT(($B$5:$B$304=B29)*($K$5:$K$304<>K29))>0),"⚠ Cap không đồng nhất","✓ OK")))) -> ✓ OK | S29: =IF(OR(B29="",E29=""),"",IF(COUNTIFS($B$5:$B29,B29,$E$5:$E29,E29)=1,MAX($S$4:$S28)+1,"")) -> 11
A30: =IF(B30="","","R"&TEXT(ROW()-4,"000")) -> R026 | B30: MB-D | C30: =IF(B30="","",IFERROR(INDEX(CARDS!$B$5:$B$34,MATCH(B30,CARDS!$A$5:$A$34,0)),"⚠ Card ID?")) -> MB | D30: =IF(B30="","",IFERROR(INDEX(CARDS!$C$5:$C$34,MATCH(B30,CARDS!$A$5:$A$34,0)),"⚠ Card ID?")) -> Cashback Demo D | E30: Groceries | F30: Groceries | G30: 5411 | H30: =IF(G30="","",IFERROR(INDEX(MCC_MASTER!$B$5:$B$504,MATCH(G30,MCC_MASTER!$A$5:$A$504,0)),"⚠ MCC chưa có trong MCC_MASTER")) -> Grocery Stores / Supermarkets | I30: 0.02 | J30: 100000 | K30: 600000 | M30: 100000 | P30: Giao dịch tối thiểu 100.000 | Q30: SAMPLE DATA — có thể xóa | R30: =IF(B30="","",IF(ISNA(MATCH(B30,CARDS!$A$5:$A$34,0)),"⚠ Card ID không tồn tại",IF(E30="","⚠ Thiếu Nhóm cashback",IF(OR(SUMPRODUCT(($B$5:$B$304=B30)*($E$5:$E$304=E30)*($J$5:$J$304<>J30))>0,SUMPRODUCT(($B$5:$B$304=B30)*($K$5:$K$304<>K30))>0),"⚠ Cap không đồng nhất","✓ OK")))) -> ✓ OK | S30: =IF(OR(B30="",E30=""),"",IF(COUNTIFS($B$5:$B30,B30,$E$5:$E30,E30)=1,MAX($S$4:$S29)+1,"")) -> 12
A31: =IF(B31="","","R"&TEXT(ROW()-4,"000")) -> R027 | B31: MB-D | C31: =IF(B31="","",IFERROR(INDEX(CARDS!$B$5:$B$34,MATCH(B31,CARDS!$A$5:$A$34,0)),"⚠ Card ID?")) -> MB | D31: =IF(B31="","",IFERROR(INDEX(CARDS!$C$5:$C$34,MATCH(B31,CARDS!$A$5:$A$34,0)),"⚠ Card ID?")) -> Cashback Demo D | E31: Shopping | F31: Shopping | G31: 5311 | H31: =IF(G31="","",IFERROR(INDEX(MCC_MASTER!$B$5:$B$504,MATCH(G31,MCC_MASTER!$A$5:$A$504,0)),"⚠ MCC chưa có trong MCC_MASTER")) -> Department Stores | I31: 0.01 | J31: 100000 | K31: 600000 | Q31: SAMPLE DATA — có thể xóa | R31: =IF(B31="","",IF(ISNA(MATCH(B31,CARDS!$A$5:$A$34,0)),"⚠ Card ID không tồn tại",IF(E31="","⚠ Thiếu Nhóm cashback",IF(OR(SUMPRODUCT(($B$5:$B$304=B31)*($E$5:$E$304=E31)*($J$5:$J$304<>J31))>0,SUMPRODUCT(($B$5:$B$304=B31)*($K$5:$K$304<>K31))>0),"⚠ Cap không đồng nhất","✓ OK")))) -> ✓ OK | S31: =IF(OR(B31="",E31=""),"",IF(COUNTIFS($B$5:$B31,B31,$E$5:$E31,E31)=1,MAX($S$4:$S30)+1,"")) -> 13
A32: =IF(B32="","","R"&TEXT(ROW()-4,"000")) | C32: =IF(B32="","",IFERROR(INDEX(CARDS!$B$5:$B$34,MATCH(B32,CARDS!$A$5:$A$34,0)),"⚠ Card ID?")) | D32: =IF(B32="","",IFERROR(INDEX(CARDS!$C$5:$C$34,MATCH(B32,CARDS!$A$5:$A$34,0)),"⚠ Card ID?")) | H32: =IF(G32="","",IFERROR(INDEX(MCC_MASTER!$B$5:$B$504,MATCH(G32,MCC_MASTER!$A$5:$A$504,0)),"⚠ MCC chưa có trong MCC_MASTER")) | R32: =IF(B32="","",IF(ISNA(MATCH(B32,CARDS!$A$5:$A$34,0)),"⚠ Card ID không tồn tại",IF(E32="","⚠ Thiếu Nhóm cashback",IF(OR(SUMPRODUCT(($B$5:$B$304=B32)*($E$5:$E$304=E32)*($J$5:$J$304<>J32))>0,SUMPRODUCT(($B$5:$B$304=B32)*($K$5:$K$304<>K32))>0),"⚠ Cap không đồng nhất","✓ OK")))) | S32: =IF(OR(B32="",E32=""),"",IF(COUNTIFS($B$5:$B32,B32,$E$5:$E32,E32)=1,MAX($S$4:$S31)+1,""))
A33: =IF(B33="","","R"&TEXT(ROW()-4,"000")) | C33: =IF(B33="","",IFERROR(INDEX(CARDS!$B$5:$B$34,MATCH(B33,CARDS!$A$5:$A$34,0)),"⚠ Card ID?")) | D33: =IF(B33="","",IFERROR(INDEX(CARDS!$C$5:$C$34,MATCH(B33,CARDS!$A$5:$A$34,0)),"⚠ Card ID?")) | H33: =IF(G33="","",IFERROR(INDEX(MCC_MASTER!$B$5:$B$504,MATCH(G33,MCC_MASTER!$A$5:$A$504,0)),"⚠ MCC chưa có trong MCC_MASTER")) | R33: =IF(B33="","",IF(ISNA(MATCH(B33,CARDS!$A$5:$A$34,0)),"⚠ Card ID không tồn tại",IF(E33="","⚠ Thiếu Nhóm cashback",IF(OR(SUMPRODUCT(($B$5:$B$304=B33)*($E$5:$E$304=E33)*($J$5:$J$304<>J33))>0,SUMPRODUCT(($B$5:$B$304=B33)*($K$5:$K$304<>K33))>0),"⚠ Cap không đồng nhất","✓ OK")))) | S33: =IF(OR(B33="",E33=""),"",IF(COUNTIFS($B$5:$B33,B33,$E$5:$E33,E33)=1,MAX($S$4:$S32)+1,""))
A34: =IF(B34="","","R"&TEXT(ROW()-4,"000")) | C34: =IF(B34="","",IFERROR(INDEX(CARDS!$B$5:$B$34,MATCH(B34,CARDS!$A$5:$A$34,0)),"⚠ Card ID?")) | D34: =IF(B34="","",IFERROR(INDEX(CARDS!$C$5:$C$34,MATCH(B34,CARDS!$A$5:$A$34,0)),"⚠ Card ID?")) | H34: =IF(G34="","",IFERROR(INDEX(MCC_MASTER!$B$5:$B$504,MATCH(G34,MCC_MASTER!$A$5:$A$504,0)),"⚠ MCC chưa có trong MCC_MASTER")) | R34: =IF(B34="","",IF(ISNA(MATCH(B34,CARDS!$A$5:$A$34,0)),"⚠ Card ID không tồn tại",IF(E34="","⚠ Thiếu Nhóm cashback",IF(OR(SUMPRODUCT(($B$5:$B$304=B34)*($E$5:$E$304=E34)*($J$5:$J$304<>J34))>0,SUMPRODUCT(($B$5:$B$304=B34)*($K$5:$K$304<>K34))>0),"⚠ Cap không đồng nhất","✓ OK")))) | S34: =IF(OR(B34="",E34=""),"",IF(COUNTIFS($B$5:$B34,B34,$E$5:$E34,E34)=1,MAX($S$4:$S33)+1,""))
A35: =IF(B35="","","R"&TEXT(ROW()-4,"000")) | C35: =IF(B35="","",IFERROR(INDEX(CARDS!$B$5:$B$34,MATCH(B35,CARDS!$A$5:$A$34,0)),"⚠ Card ID?")) | D35: =IF(B35="","",IFERROR(INDEX(CARDS!$C$5:$C$34,MATCH(B35,CARDS!$A$5:$A$34,0)),"⚠ Card ID?")) | H35: =IF(G35="","",IFERROR(INDEX(MCC_MASTER!$B$5:$B$504,MATCH(G35,MCC_MASTER!$A$5:$A$504,0)),"⚠ MCC chưa có trong MCC_MASTER")) | R35: =IF(B35="","",IF(ISNA(MATCH(B35,CARDS!$A$5:$A$34,0)),"⚠ Card ID không tồn tại",IF(E35="","⚠ Thiếu Nhóm cashback",IF(OR(SUMPRODUCT(($B$5:$B$304=B35)*($E$5:$E$304=E35)*($J$5:$J$304<>J35))>0,SUMPRODUCT(($B$5:$B$304=B35)*($K$5:$K$304<>K35))>0),"⚠ Cap không đồng nhất","✓ OK")))) | S35: =IF(OR(B35="",E35=""),"",IF(COUNTIFS($B$5:$B35,B35,$E$5:$E35,E35)=1,MAX($S$4:$S34)+1,""))
A36: =IF(B36="","","R"&TEXT(ROW()-4,"000")) | C36: =IF(B36="","",IFERROR(INDEX(CARDS!$B$5:$B$34,MATCH(B36,CARDS!$A$5:$A$34,0)),"⚠ Card ID?")) | D36: =IF(B36="","",IFERROR(INDEX(CARDS!$C$5:$C$34,MATCH(B36,CARDS!$A$5:$A$34,0)),"⚠ Card ID?")) | H36: =IF(G36="","",IFERROR(INDEX(MCC_MASTER!$B$5:$B$504,MATCH(G36,MCC_MASTER!$A$5:$A$504,0)),"⚠ MCC chưa có trong MCC_MASTER")) | R36: =IF(B36="","",IF(ISNA(MATCH(B36,CARDS!$A$5:$A$34,0)),"⚠ Card ID không tồn tại",IF(E36="","⚠ Thiếu Nhóm cashback",IF(OR(SUMPRODUCT(($B$5:$B$304=B36)*($E$5:$E$304=E36)*($J$5:$J$304<>J36))>0,SUMPRODUCT(($B$5:$B$304=B36)*($K$5:$K$304<>K36))>0),"⚠ Cap không đồng nhất","✓ OK")))) | S36: =IF(OR(B36="",E36=""),"",IF(COUNTIFS($B$5:$B36,B36,$E$5:$E36,E36)=1,MAX($S$4:$S35)+1,""))
